Workbook
Name Admin_Per_Unit: Inputs!$C$31
Name All_Checks: Checks!$C$16
Name Amort_Months: Inputs!$C$78
Name Assessed_Value_Per_Unit: Inputs!$C$25
Name BEPS_EUI_Cut: Inputs!$C$64
Name BEPS_Max_Penalty: Retrofit!$C$23
Name BEPS_Met: Retrofit!$C$22
Name BEPS_Penalty_Cap: Inputs!$C$66
Name BEPS_Penalty_Per_SF: Inputs!$C$65
Name Binding_Test: Debt!$C$13
Name Boiler_Eff: Inputs!$C$44
Name Boiler_Replace_Cost: Inputs!$C$34
Name Boiler_Replace_Year: Inputs!$C$35
Name Case_Select: Inputs!$C$89
Name Check_Balance: Checks!$C$7
Name Check_Debt_Service: Checks!$C$8
Name Check_Energy: Checks!$C$10
Name Check_Hold: Checks!$C$14
Name Check_IRR_RF: Checks!$C$13
Name Check_IRR_SQ: Checks!$C$12
Name Check_Loan_Limits: Checks!$C$6
Name Check_Shares: Checks!$C$9
Name Check_Solar: Checks!$C$11
Name Check_SU_RF: Checks!$C$5
Name Check_SU_SQ: Checks!$C$4
Name Closing_Cost_Pct: Inputs!$C$68
Name Closing_Costs: Returns!$C$14
Name Common_kWh: Energy!$C$9
Name Common_RF_kWh: Energy!$C$17
Name COP_DHW: Inputs!$C$46
Name COP_Heat: Inputs!$C$45
Name Cost_Per_tCO2e: Retrofit!$C$19
Name Debt_Constant: Debt!$C$8
Name Debt_Option: Inputs!$C$72
Name DSCR_Default: Inputs!$C$86
Name DSCR_Sizing: Inputs!$C$81
Name DSCR_Trap: Inputs!$C$85
Name DY_Default: Inputs!$C$88
Name DY_Sizing: Inputs!$C$82
Name DY_Trap: Inputs!$C$87
Name Elec_Price: Inputs!$C$41
Name Envelope_Capex: Retrofit!$C$6
Name Envelope_Capex_Per_SF: Inputs!$C$54
Name Envelope_Heat_Reduction: Inputs!$C$47
Name Equity_Multiple_RF: Returns!$C$36
Name Equity_Multiple_SQ: Returns!$C$32
Name Equity_RF: Returns!$C$19
Name Equity_SQ: Returns!$C$18
Name EUI_Base: Energy!$C$23
Name EUI_Reduction: Energy!$C$26
Name EUI_RF: Energy!$C$24
Name EUI_RF_Net_Solar: Energy!$C$25
Name Exit_Cap: Inputs!$C$70
Name Exit_Value_RF: Returns!$C$26
Name Exit_Value_SQ: Returns!$C$23
Name Exit_Value_Uplift: Retrofit!$C$17
Name Expense_Growth: Inputs!$C$22
Name Fixed_Spread: Inputs!$C$74
Name Float_Spread: Inputs!$C$76
Name g_per_kg: Inputs!$C$95

Sheet Cover
A1: Multifamily acquisition and decarbonization retrofit
A2: 150 units, Washington DC (illustrative). Status quo against an electrification + solar retrofit.
A4: Status | B4: Illustrative underwriting case built on public benchmarks. Not a real property, transaction or offer; no proprietary data.
A5: Model checks | B5: =IF(All_Checks,"All checks pass","CHECK FAILURES - see Checks tab") -> All checks pass
A6: Code version | B6: uncommitted
A7: Inputs fingerprint | B7: b49b9c9c6063
A8: Data retrieved | B8: 2026-10-15
A9: Colour convention | B9: Blue on yellow = input (Inputs tab only). Green = formula reading another tab or a named input. Black = formula on the same tab.
A10: Periods | B10: Annual. Year 1 starts at closing.
A12: Tabs
A13: Summary | B13: Key outputs, status quo against the retrofit case
A14: Inputs | B14: Every assumption with its tag (Sourced / Estimated / Illustrative / Definition) and source id
A15: Sources | B15: Citations, URLs and retrieval dates
A16: RentRoll | B16: Unit mix and year-1 gross potential rent
A17: Energy | B17: Energy by end use before and after the retrofit; EUI; Scope 1 and 2 emissions
A18: Operating | B18: Eleven-year operating statement for both cases (year 11 feeds the exit value)
A19: Debt | B19: Loan sizing (LTV, DSCR and debt-yield limits) and the amortisation schedule
A20: Covenants | B20: DSCR and debt yield by year against cash-trap and default levels, with headroom
A21: Returns | B21: Sources and uses, exit value, unlevered and levered cash flows, IRR and multiple
A22: Retrofit | B22: Retrofit capex, payback, value impact, cost per tonne and BEPS position
A23: Scenarios | B23: Base / Downside / Severe (loan held at close), one-factor sensitivities, break-even vacancy
A24: Checks | B24: Integrity checks; the Cover shows whether all pass

Sheet Summary
A1: Summary
A3: Metric | B3: Status quo | C3: Retrofit | D3: Unit
A4: Purchase price | B4: =Price -> 47000000 | C4: =Price -> 47000000 | D4: $
A5: Price per unit | B5: =Price_Per_Unit -> 313333.33 | C5: =Price_Per_Unit -> 313333.33 | D5: $
A6: Going-in cap rate | B6: =Going_In_Cap -> 0.055582121 | C6: =Going_In_Cap -> 0.055582121 | D6: %
A7: Loan amount | B7: =Loan -> 25961675 | C7: =Loan -> 25961675 | D7: $
A8: Loan to value | B8: =LTV -> 0.55237607 | C8: =LTV -> 0.55237607 | D8: %
A9: Binding sizing test | B9: =Binding_Test -> DSCR | C9: =Binding_Test -> DSCR
A10: Equity | B10: =Equity_SQ -> 22237941 | C10: =Equity_RF -> 24232221 | D10: $
A11: Minimum DSCR over hold | B11: =Min_DSCR_SQ -> 1.325833 | C11: =Min_DSCR_RF -> 1.3505448 | D11: x
A12: Minimum debt yield over hold | B12: =Min_DY_SQ -> 0.1006237 | C12: =Min_DY_RF -> 0.1024845 | D12: %
A13: Unlevered IRR | B13: =Unlev_IRR_SQ -> 0.076436281 | C13: =Unlev_IRR_RF -> 0.074426157 | D13: %
A14: Levered IRR | B14: =Lev_IRR_SQ -> 0.082077259 | C14: =Lev_IRR_RF -> 0.078015475 | D14: %
A15: Equity multiple | B15: =Equity_Multiple_SQ -> 2.0459386 | C15: =Equity_Multiple_RF -> 1.9630917 | D15: x
A16: Gross exit value | B16: =Exit_Value_SQ -> 60992474 | C16: =Exit_Value_RF -> 62067958 | D16: $
A17: Site EUI | B17: =EUI_Base -> 59.6 | C17: =EUI_RF -> 37.094778 | D17: kBtu/sf
A18: Owner Scope 1 + 2 emissions | B18: =Owner_tCO2e_SQ -> 331.58894 | C18: =Owner_tCO2e_RF -> 119.17518 | D18: tCO2e/yr
A19: Net retrofit capex | C19: =Retrofit_Net -> 1994280 | D19: $
A20: Owner utility savings, year 1 | C20: =Utility_Savings_Y1 -> 48309.585 | D20: $
A21: Simple payback | C21: =Payback_Years -> 41.281249 | D21: years
A22: Cost per tonne avoided | C22: =Cost_Per_tCO2e -> 469.43287 | D22: $/tCO2e
A23: Meets DC BEPS 20% pathway | C23: =BEPS_Met -> TRUE

Sheet Inputs
A1: Inputs
A2: Every assumption in the model, once. Tag: Sourced = read from the cited public source; Estimated = analyst assumption anchored to a source; Illustrative = deal definition; Definition = unit conversion.
I3: Stress cases: the live value in column C follows Case_Select (1 = Base, 2 = Downside, 3 = Severe)
A4: Section | B4: Input | C4: Value | D4: Unit | E4: Tag | F4: Source id | G4: Note | I4: Base | J4: Downside | K4: Severe
A5: Rent roll | B5: Studio units | C5: 20 | D5: units | E5: Illustrative | F5: asset
A6: Rent roll | B6: One-bedroom units | C6: 80 | D6: units | E6: Illustrative | F6: asset
A7: Rent roll | B7: Two-bedroom units | C7: 45 | D7: units | E7: Illustrative | F7: asset
A8: Rent roll | B8: Three-bedroom units | C8: 5 | D8: units | E8: Illustrative | F8: asset
A9: Rent roll | B9: Studio average size | C9: 520 | D9: sf | E9: Illustrative | F9: asset
A10: Rent roll | B10: One-bedroom average size | C10: 720 | D10: sf | E10: Illustrative | F10: asset
A11: Rent roll | B11: Two-bedroom average size | C11: 1000 | D11: sf | E11: Illustrative | F11: asset
A12: Rent roll | B12: Three-bedroom average size | C12: 1250 | D12: sf | E12: Illustrative | F12: asset
A13: Rent roll | B13: Studio in-place rent | C13: 1750 | D13: $/month | E13: Estimated | F13: hud_safmr_fy2026 | G13: Set inside the FY2026 DC SAFMR range
A14: Rent roll | B14: One-bedroom in-place rent | C14: 2050 | D14: $/month | E14: Estimated | F14: hud_safmr_fy2026
A15: Rent roll | B15: Two-bedroom in-place rent | C15: 2600 | D15: $/month | E15: Estimated | F15: hud_safmr_fy2026 | G15: DC ZIP 2BR SAFMRs run $2,030-$2,620
A16: Rent roll | B16: Three-bedroom in-place rent | C16: 3150 | D16: $/month | E16: Estimated | F16: hud_safmr_fy2026
A17: Rent roll | B17: Gross floor area (for EUI) | C17: 150000 | D17: sf | E17: Illustrative | F17: asset | G17: Net rentable ~119k sf; ~80% efficiency
A18: Revenue and growth | B18: Vacancy and credit loss | C18: =CHOOSE(Case_Select,I18,J18,K18) -> 0.05 | D18: % of GPR | E18: Estimated | F18: analyst | I18: 0.05 | J18: 0.07 | K18: 0.1
A19: Revenue and growth | B19: Other income (parking | C19: 1200 | D19: $/unit/yr | E19: Estimated | F19: analyst
A20: Revenue and growth | B20: Rent growth | C20: =CHOOSE(Case_Select,I20,J20,K20) -> 0.03 | D20: %/yr | E20: Estimated | F20: analyst | I20: 0.03 | J20: 0.02 | K20: 0.01
A21: Revenue and growth | B21: Other income growth | C21: 0.025 | D21: %/yr | E21: Estimated | F21: analyst
A22: Revenue and growth | B22: Operating expense growth | C22: =CHOOSE(Case_Select,I22,J22,K22) -> 0.03 | D22: %/yr | E22: Estimated | F22: analyst | I22: 0.03 | J22: 0.035 | K22: 0.04
A23: Revenue and growth | B23: Assessed value growth | C23: 0.03 | D23: %/yr | E23: Estimated | F23: analyst
A24: Revenue and growth | B24: Utility price growth (gas and power) | C24: =CHOOSE(Case_Select,I24,J24,K24) -> 0.025 | D24: %/yr | E24: Estimated | F24: analyst | I24: 0.025 | J24: 0.035 | K24: 0.05
A25: Operating expenses | B25: Assessed value | C25: 280000 | D25: $/unit | E25: Estimated | F25: analyst | G25: Kept independent of price so taxes do not loop through the purchase price
A26: Operating expenses | B26: Real property tax rate (Class 1A) | C26: 0.0085 | D26: % of assessed | E26: Sourced | F26: dc_otr_tax
A27: Operating expenses | B27: Insurance | C27: 900 | D27: $/unit/yr | E27: Estimated | F27: analyst
A28: Operating expenses | B28: Water and sewer | C28: 750 | D28: $/unit/yr | E28: Estimated | F28: analyst
A29: Operating expenses | B29: Repairs and maintenance | C29: 1100 | D29: $/unit/yr | E29: Estimated | F29: analyst
A30: Operating expenses | B30: Payroll | C30: 1800 | D30: $/unit/yr | E30: Estimated | F30: analyst
A31: Operating expenses | B31: G&A and marketing | C31: 500 | D31: $/unit/yr | E31: Estimated | F31: analyst
A32: Operating expenses | B32: Management fee | C32: 0.03 | D32: % of EGI | E32: Estimated | F32: analyst
A33: Operating expenses | B33: Replacement reserves | C33: 300 | D33: $/unit/yr | E33: Estimated | F33: analyst | G33: Agency-style underwriting level
A34: Operating expenses | B34: Boiler replacement (status quo only) | C34: 450000 | D34: $ | E34: Estimated | F34: analyst | G34: Avoided if the plant is electrified
A35: Operating expenses | B35: Boiler replacement year | C35: 3 | D35: year | E35: Illustrative | F35: asset
A36: Energy baseline | B36: Baseline site EUI | C36: 59.6 | D36: kBtu/sf/yr | E36: Sourced | F36: estar_median | G36: Building assumed at the national multifamily median
A37: Energy baseline | B37: End-use share: space heating (gas, central) | C37: 0.28 | D37: % of site energy | E37: Estimated | F37: recs_2020
A38: Energy baseline | B38: End-use share: domestic hot water (gas, central) | C38: 0.22 | D38: % of site energy | E38: Estimated | F38: recs_2020
A39: Energy baseline | B39: End-use share: common-area electricity (owner-paid) | C39: 0.12 | D39: % of site energy | E39: Estimated | F39: analyst
A40: Energy baseline | B40: End-use share: in-unit electricity (tenant-paid) | C40: 0.38 | D40: % of site energy | E40: Estimated | F40: recs_2020
...

Sheet Sources
A1: Sources
A3: Source id | B3: Citation | C3: URL | D3: Retrieved
A4: estar_median | B4: ENERGY STAR Portfolio Manager, U.S. National Median Table (August 2024): Multifamily Housing site EUI 59.6 kBtu/ft2, source EUI 118.1 | C4: https://portfoliomanager.energystar.gov/pdf/reference/US%20National%20Median%20Table.pdf | D4: 2026-10-15
A5: recs_2020 | B5: EIA Residential Energy Consumption Survey 2020, end-use consumption tables (CE3.x) for apartments in buildings with 5+ units, by census region | C5: https://www.eia.gov/consumption/residential/data/2020/ | D5: 2026-10-15
A6: eia_epa_2_10 | B6: EIA Electric Power Annual, Table 2.10: District of Columbia average price to commercial customers, 17.07 cents/kWh (2024) | C6: https://www.eia.gov/electricity/annual/html/epa_02_10.html | D6: 2026-10-15
A7: eia_ng_dc | B7: EIA Natural Gas Navigator, District of Columbia price delivered to commercial consumers (N3020DC3), $14.36/Mcf (2025 annual, released 2026-09-30) | C7: https://www.eia.gov/dnav/ng/hist/n3020dc3a.htm | D7: 2026-10-15
A8: epa_ef_hub_2025 | B8: EPA GHG Emission Factors Hub (January 2025), Table 1: natural gas 53.06 kg CO2, 1.0 g CH4, 0.10 g N2O per mmBtu; 0.001026 mmBtu/scf; GWP CH4 28, N2O 265 | C8: https://www.epa.gov/system/files/documents/2025-01/ghg-emission-factors-hub-2025.pdf | D8: 2026-10-15
A9: egrid2022 | B9: EPA eGRID2022 Summary Tables: total output emission rates, RFC East (RFCE) 660.3 lb CO2e/MWh; ERCOT All (ERCT) 774.3 lb CO2e/MWh; U.S. 827.5 lb CO2e/MWh | C9: https://www.epa.gov/system/files/documents/2024-01/egrid2022_summary_tables.pdf | D9: 2026-10-15
A10: atb_2024b_commercial_pv | B10: NREL/NLR Annual Technology Baseline 2024b, Commercial PV: CAPEX $1.78/Wdc (2023), fixed O&M ~$19/kWdc-yr; 200 kWdc flat-roof reference system | C10: https://atb.nlr.gov/electricity/2024b/commercial_pv | D10: 2026-10-15
A11: pvwatts_v8 | B11: NREL/NLR PVWatts v8.5 API run, Washington DC (38.90, -77.03), fixed roof mount, tilt 10, azimuth 180, 14% losses, DC/AC 1.2: 1,317.7 kWh AC per kWdc per year | C11: https://developer.nlr.gov/docs/solar/pvwatts/v8/ | D11: 2026-10-15
A12: hud_safmr_fy2026 | B12: HUD FY2026 Small Area Fair Market Rents, Washington-Arlington-Alexandria HUD Metro FMR Area; DC ZIP 2BR SAFMRs $2,030 (20011) to $2,620 (20024), read via the fairmarketrentmap.com mirror of HUD data | C12: https://www.huduser.gov/portal/datasets/fmr/smallarea/index.html | D12: 2026-10-15
A13: dc_otr_tax | B13: DC Office of Tax and Revenue: Class 1A real property tax rate (residential, 3+ units) $0.85 per $100 of assessed value | C13: https://otr.cfo.dc.gov/page/real-property-tax-rates | D13: 2026-10-15
A14: doee_beps | B14: DC DOEE Building Energy Performance Standards Compliance Guidebook (Aug 2021) and Perkins Eastman BEPS guide: performance pathway = 20% site EUI reduction; penalty up to $10/ft2, capped at $7.5 million, prorated by progress. Cycle 2 (from 2027) assumed to carry the same structure. | C14: https://doee.dc.gov/service/building-energy-performance-standards-beps | D14: 2026-10-15
... A17: fred_sofr | B17: FRED SOFR, Secured Overnight Financing Rate, 3.88% on 2026-10-14 (fetched with quantlab.data.sources.extra.fred_series) | C17: https://fred.stlouisfed.org/series/SOFR | D17: 2026-10-15
A18: asset | B18: Illustrative asset definition for this model (unit mix, size, deal terms). Not a real property or transaction. | D18: 2026-10-15
A19: analyst | B19: Analyst estimate, stated in the input note. Not taken from a single published figure; treat as an assumption to stress. | D19: 2026-10-15
A20: definition | B20: Unit conversion or definition (e.g. 12 months per year, 3,412.14 Btu per kWh, 2,204.62 lb per metric ton). | D20: 2026-10-15

Sheet RentRoll
A1: Rent roll
A2: Year-1 in-place rents; growth is applied on the Operating tab.
A4: Unit type | B4: Units | C4: Avg size (sf) | D4: Rent ($/month) | E4: Annual GPR | F4: Total sf
A5: Studio | B5: =Units_Studio -> 20 | C5: =SF_Studio -> 520 | D5: =Rent_Studio -> 1750 | E5: =B5*D5*Months -> 420000 | F5: =B5*C5 -> 10400
A6: 1BR | B6: =Units_1BR -> 80 | C6: =SF_1BR -> 720 | D6: =Rent_1BR -> 2050 | E6: =B6*D6*Months -> 1968000 | F6: =B6*C6 -> 57600
A7: 2BR | B7: =Units_2BR -> 45 | C7: =SF_2BR -> 1000 | D7: =Rent_2BR -> 2600 | E7: =B7*D7*Months -> 1404000 | F7: =B7*C7 -> 45000
A8: 3BR | B8: =Units_3BR -> 5 | C8: =SF_3BR -> 1250 | D8: =Rent_3BR -> 3150 | E8: =B8*D8*Months -> 189000 | F8: =B8*C8 -> 6250
A9: Total | B9: =SUM(B5:B8) -> 150 | D9: =E9/B9/Months -> 2211.6667 | E9: =SUM(E5:E8) -> 3981000 | F9: =SUM(F5:F8) -> 119250

Sheet Energy
A1: Energy and emissions
A2: Annual quantities, held flat over the hold. Whole-building site EUI follows ENERGY STAR (on-site solar consumed counts as site energy).
A4: Baseline (status quo)
A5: Site energy | B5: MMBtu/yr | C5: =GFA*Site_EUI_Base/kBtu_per_MMBtu -> 8940
A6: Gas, space heating | B6: MMBtu/yr | C6: =Site_MMBtu_Base*Share_Heat_Gas -> 2503.2
A7: Gas, hot water | B7: MMBtu/yr | C7: =Site_MMBtu_Base*Share_DHW_Gas -> 1966.8
A8: Gas, owner-paid total | B8: MMBtu/yr | C8: =Gas_Heat_MMBtu+Gas_DHW_MMBtu -> 4470
A9: Electricity, common areas (owner) | B9: kWh/yr | C9: =Site_MMBtu_Base*Share_Common_Elec*kWh_per_MMBtu -> 314406.68
A10: Electricity, in-unit (tenant) | B10: kWh/yr | C10: =Site_MMBtu_Base*Share_Tenant_Elec*kWh_per_MMBtu -> 995621.14
A11: Gas price | B11: $/MMBtu | C11: =Gas_Price_Mcf/Gas_MMBtu_Per_Mcf -> 13.996101
A13: Retrofit
A14: Heat pump electricity, space heating | B14: kWh/yr | C14: =Gas_Heat_MMBtu*(1-Gas_Retained_Share)*Boiler_Eff*(1-Envelope_Heat_Reduction)/COP_Heat*kWh_per_MMBtu -> 203155.08
A15: Heat pump electricity, hot water | B15: kWh/yr | C15: =Gas_DHW_MMBtu*(1-Gas_Retained_Share)*Boiler_Eff/COP_DHW*kWh_per_MMBtu -> 164689.21
A16: Gas retained | B16: MMBtu/yr | C16: =Gas_SQ_MMBtu*Gas_Retained_Share -> 0
A17: Common-area electricity after LEDs | B17: kWh/yr | C17: =Common_kWh*(1-LED_Savings) -> 267245.67
A18: Owner electricity use | B18: kWh/yr | C18: =Common_RF_kWh+HP_Heat_kWh+HP_DHW_kWh -> 635089.97
A19: Rooftop solar generation | B19: kWh/yr | C19: =Solar_kWdc*Solar_Yield -> 237186
A20: Owner grid purchases | B20: kWh/yr | C20: =Owner_Gross_RF_kWh-Solar_kWh -> 397903.97
A22: Energy use intensity
A23: Site EUI, status quo | B23: kBtu/sf | C23: =Site_EUI_Base -> 59.6
A24: Site EUI, retrofit | B24: kBtu/sf | C24: =(Tenant_kWh+Owner_Gross_RF_kWh+Gas_RF_MMBtu*kWh_per_MMBtu)*kBtu_per_MMBtu/kWh_per_MMBtu/GFA -> 37.094778
A25: Site EUI net of on-site solar | B25: kBtu/sf | C25: =(Tenant_kWh+Grid_RF_kWh+Gas_RF_MMBtu*kWh_per_MMBtu)*kBtu_per_MMBtu/kWh_per_MMBtu/GFA -> 31.699364
A26: Site EUI reduction | B26: % | C26: =1-EUI_RF/EUI_Base -> 0.3776044
A28: Emissions
A29: Natural gas factor (CO2 + CH4 + N2O) | B29: tCO2e/MMBtu | C29: =(NG_CO2_kg_MMBtu+(NG_CH4_g_MMBtu*GWP_CH4+NG_N2O_g_MMBtu*GWP_N2O)/g_per_kg)/kg_per_t -> 0.0531145
A30: Grid factor | B30: tCO2e/kWh | C30: =Grid_CO2e_lb_MWh/kWh_per_MWh/lb_per_t -> 0.0002995074
A31: Scope 1, status quo (owner gas) | B31: tCO2e/yr | C31: =Gas_SQ_MMBtu*NG_tCO2e_MMBtu -> 237.42182
A32: Scope 2, status quo (owner electricity) | B32: tCO2e/yr | C32: =Common_kWh*Grid_tCO2e_kWh -> 94.167125
A33: Scope 1, retrofit | B33: tCO2e/yr | C33: =Gas_RF_MMBtu*NG_tCO2e_MMBtu -> 0
A34: Scope 2, retrofit | B34: tCO2e/yr | C34: =Grid_RF_kWh*Grid_tCO2e_kWh -> 119.17518
A35: Tenant electricity (Scope 3, cat. 13), both cases | B35: tCO2e/yr | C35: =Tenant_kWh*Grid_tCO2e_kWh -> 298.1959
A36: Owner Scope 1 + 2, status quo | B36: tCO2e/yr | C36: =Scope1_SQ+Scope2_SQ -> 331.58894
A37: Owner Scope 1 + 2, retrofit | B37: tCO2e/yr | C37: =Scope1_RF+Scope2_RF -> 119.17518
A38: Owner emissions avoided | B38: tCO2e/yr | C38: =Owner_tCO2e_SQ-Owner_tCO2e_RF -> 212.41376

Sheet Operating
A1: Operating statement
A2: Common lines are shared; utilities, NOI and cash flow are shown for both cases. SQ = status quo, RF = retrofit.
A4: Year | B4: Unit | D4: 1 | E4: =D4+1 -> 2 | F4: =E4+1 -> 3 | G4: =F4+1 -> 4 | H4: =G4+1 -> 5 | I4: =H4+1 -> 6 | J4: =I4+1 -> 7 | K4: =J4+1 -> 8 | L4: =K4+1 -> 9 | ... N4: =M4+1 -> 11
A5: Indices
A6: Rent | B6: index | D6: =(1+Rent_Growth)^(D4-1) -> 1 | E6: =(1+Rent_Growth)^(E4-1) -> 1.03 | F6: =(1+Rent_Growth)^(F4-1) -> 1.0609 | G6: =(1+Rent_Growth)^(G4-1) -> 1.092727 | H6: =(1+Rent_Growth)^(H4-1) -> 1.1255088 | I6: =(1+Rent_Growth)^(I4-1) -> 1.1592741 | J6: =(1+Rent_Growth)^(J4-1) -> 1.1940523 | K6: =(1+Rent_Growth)^(K4-1) -> 1.2298739 | ... N6: =(1+Rent_Growth)^(N4-1) -> 1.3439164
A7: Other income | B7: index | D7: =(1+Other_Income_Growth)^(D4-1) -> 1 | E7: =(1+Other_Income_Growth)^(E4-1) -> 1.025 | F7: =(1+Other_Income_Growth)^(F4-1) -> 1.050625 | G7: =(1+Other_Income_Growth)^(G4-1) -> 1.0768906 | H7: =(1+Other_Income_Growth)^(H4-1) -> 1.1038129 | I7: =(1+Other_Income_Growth)^(I4-1) -> 1.1314082 | J7: =(1+Other_Income_Growth)^(J4-1) -> 1.1596934 | K7: =(1+Other_Income_Growth)^(K4-1) -> 1.1886858 | ... N7: =(1+Other_Income_Growth)^(N4-1) -> 1.2800845
A8: Operating expenses | B8: index | D8: =(1+Expense_Growth)^(D4-1) -> 1 | E8: =(1+Expense_Growth)^(E4-1) -> 1.03 | F8: =(1+Expense_Growth)^(F4-1) -> 1.0609 | G8: =(1+Expense_Growth)^(G4-1) -> 1.092727 | H8: =(1+Expense_Growth)^(H4-1) -> 1.1255088 | I8: =(1+Expense_Growth)^(I4-1) -> 1.1592741 | J8: =(1+Expense_Growth)^(J4-1) -> 1.1940523 | K8: =(1+Expense_Growth)^(K4-1) -> 1.2298739 | ... N8: =(1+Expense_Growth)^(N4-1) -> 1.3439164
A9: Assessed value | B9: index | D9: =(1+Tax_Growth)^(D4-1) -> 1 | E9: =(1+Tax_Growth)^(E4-1) -> 1.03 | F9: =(1+Tax_Growth)^(F4-1) -> 1.0609 | G9: =(1+Tax_Growth)^(G4-1) -> 1.092727 | H9: =(1+Tax_Growth)^(H4-1) -> 1.1255088 | I9: =(1+Tax_Growth)^(I4-1) -> 1.1592741 | J9: =(1+Tax_Growth)^(J4-1) -> 1.1940523 | K9: =(1+Tax_Growth)^(K4-1) -> 1.2298739 | ... N9: =(1+Tax_Growth)^(N4-1) -> 1.3439164
A10: Utility prices | B10: index | D10: =(1+Utility_Price_Growth)^(D4-1) -> 1 | E10: =(1+Utility_Price_Growth)^(E4-1) -> 1.025 | F10: =(1+Utility_Price_Growth)^(F4-1) -> 1.050625 | G10: =(1+Utility_Price_Growth)^(G4-1) -> 1.0768906 | H10: =(1+Utility_Price_Growth)^(H4-1) -> 1.1038129 | I10: =(1+Utility_Price_Growth)^(I4-1) -> 1.1314082 | J10: =(1+Utility_Price_Growth)^(J4-1) -> 1.1596934 | K10: =(1+Utility_Price_Growth)^(K4-1) -> 1.1886858 | ... N10: =(1+Utility_Price_Growth)^(N4-1) -> 1.2800845
A12: Revenue
A13: Gross potential rent | B13: $ | D13: =GPR_Y1*D6 -> 3981000 | E13: =GPR_Y1*E6 -> 4100430 | F13: =GPR_Y1*F6 -> 4223442.9 | G13: =GPR_Y1*G6 -> 4350146.2 | H13: =GPR_Y1*H6 -> 4480650.6 | I13: =GPR_Y1*I6 -> 4615070.1 | J13: =GPR_Y1*J6 -> 4753522.2 | K13: =GPR_Y1*K6 -> 4896127.9 | ... N13: =GPR_Y1*N6 -> 5350131.1
A14: Vacancy and credit loss | B14: $ | D14: =-D13*Vacancy_Rate -> -199050 | E14: =-E13*Vacancy_Rate -> -205021.5 | F14: =-F13*Vacancy_Rate -> -211172.14 | G14: =-G13*Vacancy_Rate -> -217507.31 | H14: =-H13*Vacancy_Rate -> -224032.53 | I14: =-I13*Vacancy_Rate -> -230753.5 | J14: =-J13*Vacancy_Rate -> -237676.11 | K14: =-K13*Vacancy_Rate -> -244806.39 | ... N14: =-N13*Vacancy_Rate -> -267506.56
A15: Other income | B15: $ | D15: =Other_Income_Per_Unit*Units*D7 -> 180000 | E15: =Other_Income_Per_Unit*Units*E7 -> 184500 | F15: =Other_Income_Per_Unit*Units*F7 -> 189112.5 | G15: =Other_Income_Per_Unit*Units*G7 -> 193840.31 | H15: =Other_Income_Per_Unit*Units*H7 -> 198686.32 | I15: =Other_Income_Per_Unit*Units*I7 -> 203653.48 | J15: =Other_Income_Per_Unit*Units*J7 -> 208744.82 | K15: =Other_Income_Per_Unit*Units*K7 -> 213963.44 | ... N15: =Other_Income_Per_Unit*Units*N7 -> 230415.22
A16: Effective gross income | B16: $ | D16: =D13+D14+D15 -> 3961950 | E16: =E13+E14+E15 -> 4079908.5 | F16: =F13+F14+F15 -> 4201383.3 | G16: =G13+G14+G15 -> 4326479.2 | H16: =H13+H14+H15 -> 4455304.4 | I16: =I13+I14+I15 -> 4587970.1 | J16: =J13+J14+J15 -> 4724590.9 | K16: =K13+K14+K15 -> 4865284.9 | ... N16: =N13+N14+N15 -> 5313039.8
A18: Operating expenses (shared)
A19: Real estate taxes | B19: $ | D19: =Assessed_Value_Per_Unit*Units*Tax_Rate*D9 -> 357000 | E19: =Assessed_Value_Per_Unit*Units*Tax_Rate*E9 -> 367710 | F19: =Assessed_Value_Per_Unit*Units*Tax_Rate*F9 -> 378741.3 | G19: =Assessed_Value_Per_Unit*Units*Tax_Rate*G9 -> 390103.54 | H19: =Assessed_Value_Per_Unit*Units*Tax_Rate*H9 -> 401806.65 | I19: =Assessed_Value_Per_Unit*Units*Tax_Rate*I9 -> 413860.84 | J19: =Assessed_Value_Per_Unit*Units*Tax_Rate*J9 -> 426276.67 | K19: =Assessed_Value_Per_Unit*Units*Tax_Rate*K9 -> 439064.97 | ... N19: =Assessed_Value_Per_Unit*Units*Tax_Rate*N9 -> 479778.15
A20: Insurance | B20: $ | D20: =Insurance_Per_Unit*Units*D8 -> 135000 | E20: =Insurance_Per_Unit*Units*E8 -> 139050 | F20: =Insurance_Per_Unit*Units*F8 -> 143221.5 | G20: =Insurance_Per_Unit*Units*G8 -> 147518.14 | H20: =Insurance_Per_Unit*Units*H8 -> 151943.69 | I20: =Insurance_Per_Unit*Units*I8 -> 156502 | J20: =Insurance_Per_Unit*Units*J8 -> 161197.06 | K20: =Insurance_Per_Unit*Units*K8 -> 166032.97 | ... N20: =Insurance_Per_Unit*Units*N8 -> 181428.71
A21: Water and sewer | B21: $ | D21: =Water_Sewer_Per_Unit*Units*D8 -> 112500 | E21: =Water_Sewer_Per_Unit*Units*E8 -> 115875 | F21: =Water_Sewer_Per_Unit*Units*F8 -> 119351.25 | G21: =Water_Sewer_Per_Unit*Units*G8 -> 122931.79 | H21: =Water_Sewer_Per_Unit*Units*H8 -> 126619.74 | I21: =Water_Sewer_Per_Unit*Units*I8 -> 130418.33 | J21: =Water_Sewer_Per_Unit*Units*J8 -> 134330.88 | K21: =Water_Sewer_Per_Unit*Units*K8 -> 138360.81 | ... N21: =Water_Sewer_Per_Unit*Units*N8 -> 151190.59
A22: Repairs and maintenance | B22: $ | D22: =Repairs_Per_Unit*Units*D8 -> 165000 | E22: =Repairs_Per_Unit*Units*E8 -> 169950 | F22: =Repairs_Per_Unit*Units*F8 -> 175048.5 | G22: =Repairs_Per_Unit*Units*G8 -> 180299.95 | H22: =Repairs_Per_Unit*Units*H8 -> 185708.95 | I22: =Repairs_Per_Unit*Units*I8 -> 191280.22 | J22: =Repairs_Per_Unit*Units*J8 -> 197018.63 | K22: =Repairs_Per_Unit*Units*K8 -> 202929.19 | ... N22: =Repairs_Per_Unit*Units*N8 -> 221746.2
A23: Payroll | B23: $ | D23: =Payroll_Per_Unit*Units*D8 -> 270000 | E23: =Payroll_Per_Unit*Units*E8 -> 278100 | F23: =Payroll_Per_Unit*Units*F8 -> 286443 | G23: =Payroll_Per_Unit*Units*G8 -> 295036.29 | H23: =Payroll_Per_Unit*Units*H8 -> 303887.38 | I23: =Payroll_Per_Unit*Units*I8 -> 313004 | J23: =Payroll_Per_Unit*Units*J8 -> 322394.12 | K23: =Payroll_Per_Unit*Units*K8 -> 332065.94 | ... N23: =Payroll_Per_Unit*Units*N8 -> 362857.42
A24: G&A and marketing | B24: $ | D24: =Admin_Per_Unit*Units*D8 -> 75000 | E24: =Admin_Per_Unit*Units*E8 -> 77250 | F24: =Admin_Per_Unit*Units*F8 -> 79567.5 | G24: =Admin_Per_Unit*Units*G8 -> 81954.525 | H24: =Admin_Per_Unit*Units*H8 -> 84413.161 | I24: =Admin_Per_Unit*Units*I8 -> 86945.556 | J24: =Admin_Per_Unit*Units*J8 -> 89553.922 | K24: =Admin_Per_Unit*Units*K8 -> 92240.54 | ... N24: =Admin_Per_Unit*Units*N8 -> 100793.73
A25: Management fee | B25: $ | D25: =Mgmt_Fee_Pct*D16 -> 118858.5 | E25: =Mgmt_Fee_Pct*E16 -> 122397.25 | F25: =Mgmt_Fee_Pct*F16 -> 126041.5 | G25: =Mgmt_Fee_Pct*G16 -> 129794.38 | H25: =Mgmt_Fee_Pct*H16 -> 133659.13 | I25: =Mgmt_Fee_Pct*I16 -> 137639.1 | J25: =Mgmt_Fee_Pct*J16 -> 141737.73 | K25: =Mgmt_Fee_Pct*K16 -> 145958.55 | ... N25: =Mgmt_Fee_Pct*N16 -> 159391.19
A26: Shared operating expenses | B26: $ | D26: =D19+D20+D21+D22+D23+D24+D25 -> 1233358.5 | E26: =E19+E20+E21+E22+E23+E24+E25 -> 1270332.3 | F26: =F19+F20+F21+F22+F23+F24+F25 -> 1308414.5 | G26: =G19+G20+G21+G22+G23+G24+G25 -> 1347638.6 | H26: =H19+H20+H21+H22+H23+H24+H25 -> 1388038.7 | I26: =I19+I20+I21+I22+I23+I24+I25 -> 1429650.1 | J26: =J19+J20+J21+J22+J23+J24+J25 -> 1472509 | K26: =K19+K20+K21+K22+K23+K24+K25 -> 1516653 | ... N26: =N19+N20+N21+N22+N23+N24+N25 -> 1657186
A28: Owner-paid utilities
A29: Gas, status quo | B29: $ | D29: =Gas_SQ_MMBtu*Gas_Price_MMBtu*D10 -> 62562.573 | E29: =Gas_SQ_MMBtu*Gas_Price_MMBtu*E10 -> 64126.637 | F29: =Gas_SQ_MMBtu*Gas_Price_MMBtu*F10 -> 65729.803 | G29: =Gas_SQ_MMBtu*Gas_Price_MMBtu*G10 -> 67373.048 | H29: =Gas_SQ_MMBtu*Gas_Price_MMBtu*H10 -> 69057.375 | I29: =Gas_SQ_MMBtu*Gas_Price_MMBtu*I10 -> 70783.809 | J29: =Gas_SQ_MMBtu*Gas_Price_MMBtu*J10 -> 72553.404 | K29: =Gas_SQ_MMBtu*Gas_Price_MMBtu*K10 -> 74367.239 | ... N29: =Gas_SQ_MMBtu*Gas_Price_MMBtu*N10 -> 80085.383
A30: Electricity, status quo | B30: $ | D30: =Common_kWh*Elec_Price*D10 -> 53669.22 | E30: =Common_kWh*Elec_Price*E10 -> 55010.95 | F30: =Common_kWh*Elec_Price*F10 -> 56386.224 | G30: =Common_kWh*Elec_Price*G10 -> 57795.879 | H30: =Common_kWh*Elec_Price*H10 -> 59240.776 | I30: =Common_kWh*Elec_Price*I10 -> 60721.796 | J30: =Common_kWh*Elec_Price*J10 -> 62239.841 | K30: =Common_kWh*Elec_Price*K10 -> 63795.837 | ... N30: =Common_kWh*Elec_Price*N10 -> 68701.139
A31: Gas, retrofit | B31: $ | D31: =Gas_RF_MMBtu*Gas_Price_MMBtu*D10 -> 0 | E31: =Gas_RF_MMBtu*Gas_Price_MMBtu*E10 -> 0 | F31: =Gas_RF_MMBtu*Gas_Price_MMBtu*F10 -> 0 | G31: =Gas_RF_MMBtu*Gas_Price_MMBtu*G10 -> 0 | H31: =Gas_RF_MMBtu*Gas_Price_MMBtu*H10 -> 0 | I31: =Gas_RF_MMBtu*Gas_Price_MMBtu*I10 -> 0 | J31: =Gas_RF_MMBtu*Gas_Price_MMBtu*J10 -> 0 | K31: =Gas_RF_MMBtu*Gas_Price_MMBtu*K10 -> 0 | ... N31: =Gas_RF_MMBtu*Gas_Price_MMBtu*N10 -> 0
A32: Electricity, retrofit (grid purchases) | B32: $ | D32: =Grid_RF_kWh*Elec_Price*D10 -> 67922.208 | E32: =Grid_RF_kWh*Elec_Price*E10 -> 69620.263 | F32: =Grid_RF_kWh*Elec_Price*F10 -> 71360.769 | G32: =Grid_RF_kWh*Elec_Price*G10 -> 73144.788 | H32: =Grid_RF_kWh*Elec_Price*H10 -> 74973.408 | I32: =Grid_RF_kWh*Elec_Price*I10 -> 76847.743 | J32: =Grid_RF_kWh*Elec_Price*J10 -> 78768.937 | K32: =Grid_RF_kWh*Elec_Price*K10 -> 80738.16 | ... N32: =Grid_RF_kWh*Elec_Price*N10 -> 86946.168
A34: Net operating income and cash flow
A35: Total operating expenses, SQ | B35: $ | D35: =D26+D29+D30 -> 1349590.3 | E35: =E26+E29+E30 -> 1389469.8 | F35: =F26+F29+F30 -> 1430530.6 | G35: =G26+G29+G30 -> 1472807.5 | H35: =H26+H29+H30 -> 1516336.9 | I35: =I26+I29+I30 -> 1561155.7 | J35: =J26+J29+J30 -> 1607302.3 | K35: =K26+K29+K30 -> 1654816 | ... N35: =N26+N29+N30 -> 1805972.5
A36: Total operating expenses, RF | B36: $ | D36: =D26+D31+D32 -> 1301280.7 | E36: =E26+E31+E32 -> 1339952.5 | F36: =F26+F31+F32 -> 1379775.3 | G36: =G26+G31+G32 -> 1420783.4 | H36: =H26+H31+H32 -> 1463012.1 | I36: =I26+I31+I32 -> 1506497.8 | J36: =J26+J31+J32 -> 1551277.9 | K36: =K26+K31+K32 -> 1597391.1 | ... N36: =N26+N31+N32 -> 1744132.2
A37: Net operating income, SQ | B37: $ | D37: =D16-D35 -> 2612359.7 | E37: =E16-E35 -> 2690438.7 | F37: =F16-F35 -> 2770852.7 | G37: =G16-G35 -> 2853671.6 | H37: =H16-H35 -> 2938967.5 | I37: =I16-I35 -> 3026814.4 | J37: =J16-J35 -> 3117288.6 | K37: =K16-K35 -> 3210468.9 | ... N37: =N16-N35 -> 3507067.2
A38: Net operating income, RF | B38: $ | D38: =D16-D36 -> 2660669.3 | E38: =E16-E36 -> 2739956 | F38: =F16-F36 -> 2821607.9 | G38: =G16-G36 -> 2905695.8 | H38: =H16-H36 -> 2992292.3 | I38: =I16-I36 -> 3081472.3 | J38: =J16-J36 -> 3173312.9 | K38: =K16-K36 -> 3267893.8 | ... N38: =N16-N36 -> 3568907.6
A39: Replacement reserves | B39: $ | D39: =Reserve_Per_Unit*Units*D8 -> 45000 | E39: =Reserve_Per_Unit*Units*E8 -> 46350 | F39: =Reserve_Per_Unit*Units*F8 -> 47740.5 | G39: =Reserve_Per_Unit*Units*G8 -> 49172.715 | H39: =Reserve_Per_Unit*Units*H8 -> 50647.896 | I39: =Reserve_Per_Unit*Units*I8 -> 52167.333 | J39: =Reserve_Per_Unit*Units*J8 -> 53732.353 | K39: =Reserve_Per_Unit*Units*K8 -> 55344.324 | ... N39: =Reserve_Per_Unit*Units*N8 -> 60476.237
A40: Net cash flow after reserves, SQ | B40: $ | D40: =D37-D39 -> 2567359.7 | E40: =E37-E39 -> 2644088.7 | F40: =F37-F39 -> 2723112.2 | G40: =G37-G39 -> 2804498.9 | H40: =H37-H39 -> 2888319.6 | I40: =I37-I39 -> 2974647.1 | J40: =J37-J39 -> 3063556.3 | K40: =K37-K39 -> 3155124.5 | ... N40: =N37-N39 -> 3446591
A41: Net cash flow after reserves, RF | B41: $ | D41: =D38-D39 -> 2615669.3 | E41: =E38-E39 -> 2693606 | F41: =F38-F39 -> 2773867.4 | G41: =G38-G39 -> 2856523.1 | H41: =H38-H39 -> 2941644.4 | I41: =I38-I39 -> 3029304.9 | J41: =J38-J39 -> 3119580.6 | K41: =K38-K39 -> 3212549.4 | ... N41: =N38-N39 -> 3508431.4
A42: Boiler replacement (status quo only) | B42: $ | D42: =IF(D4=Boiler_Replace_Year,Boiler_Replace_Cost*D8,0) -> 0 | E42: =IF(E4=Boiler_Replace_Year,Boiler_Replace_Cost*E8,0) -> 0 | F42: =IF(F4=Boiler_Replace_Year,Boiler_Replace_Cost*F8,0) -> 477405 | G42: =IF(G4=Boiler_Replace_Year,Boiler_Replace_Cost*G8,0) -> 0 | H42: =IF(H4=Boiler_Replace_Year,Boiler_Replace_Cost*H8,0) -> 0 | I42: =IF(I4=Boiler_Replace_Year,Boiler_Replace_Cost*I8,0) -> 0 | J42: =IF(J4=Boiler_Replace_Year,Boiler_Replace_Cost*J8,0) -> 0 | K42: =IF(K4=Boiler_Replace_Year,Boiler_Replace_Cost*K8,0) -> 0 | ... N42: =IF(N4=Boiler_Replace_Year,Boiler_Replace_Cost*N8,0) -> 0

Sheet Debt
A1: Debt
A2: Sized on status-quo year-1 cash flow; the same loan funds both cases. Monthly payments, shown annually.
A4: Year | B4: Unit | D4: 1 | E4: =D4+1 -> 2 | F4: =E4+1 -> 3 | G4: =F4+1 -> 4 | H4: =G4+1 -> 5 | I4: =H4+1 -> 6 | J4: =I4+1 -> 7 | K4: =J4+1 -> 8 | L4: =K4+1 -> 9 | ... N4: =M4+1 -> 11
A5: Sizing
A6: Fixed rate (Treasury + spread) | B6: % | C6: =UST_10Y+Fixed_Spread -> 0.0691
A7: Floating rate (SOFR + shock + spread) | B7: % | C7: =SOFR+SOFR_Shock+Float_Spread -> 0.0678
A8: Annual debt constant (amortising) | B8: % | C8: =PMT(D21/Months,Amort_Months,-1)*Months -> 0.079112297
A9: Maximum loan, LTV test | B9: $ | C9: =LTV_Max*Price -> 30550000
A10: Maximum loan, DSCR test | B10: $ | C10: =Operating!D40/(DSCR_Sizing*Debt_Constant) -> 25961675
A11: Maximum loan, debt-yield test | B11: $ | C11: =Operating!D37/DY_Sizing -> 32654496
A12: Loan amount | B12: $ | C12: =IF(Loan_Override>0,Loan_Override,MIN(Max_Loan_LTV,Max_Loan_DSCR,Max_Loan_DY)) -> 25961675
A13: Binding constraint | C13: =IF(Loan_Override>0,"Override",IF(Loan=Max_Loan_DSCR,"DSCR",IF(Loan=Max_Loan_LTV,"LTV","Debt yield"))) -> DSCR
A14: Loan to value | B14: % | C14: =Loan/Price -> 0.55237607
A20: Schedule
A21: Interest rate | B21: % | D21: =IF(Debt_Option=1,Rate_Fixed,Rate_Float) -> 0.0691 | E21: =IF(Debt_Option=1,Rate_Fixed,Rate_Float) -> 0.0691 | F21: =IF(Debt_Option=1,Rate_Fixed,Rate_Float) -> 0.0691 | G21: =IF(Debt_Option=1,Rate_Fixed,Rate_Float) -> 0.0691 | H21: =IF(Debt_Option=1,Rate_Fixed,Rate_Float) -> 0.0691 | I21: =IF(Debt_Option=1,Rate_Fixed,Rate_Float) -> 0.0691 | J21: =IF(Debt_Option=1,Rate_Fixed,Rate_Float) -> 0.0691 | K21: =IF(Debt_Option=1,Rate_Fixed,Rate_Float) -> 0.0691 | ... N21: =IF(Debt_Option=1,Rate_Fixed,Rate_Float) -> 0.0691
A22: Interest-only year (1 = yes) | B22: flag | D22: =IF(D4<=IO_Years,1,0) -> 1 | E22: =IF(E4<=IO_Years,1,0) -> 1 | F22: =IF(F4<=IO_Years,1,0) -> 0 | G22: =IF(G4<=IO_Years,1,0) -> 0 | H22: =IF(H4<=IO_Years,1,0) -> 0 | I22: =IF(I4<=IO_Years,1,0) -> 0 | J22: =IF(J4<=IO_Years,1,0) -> 0 | K22: =IF(K4<=IO_Years,1,0) -> 0 | ... N22: =IF(N4<=IO_Years,1,0) -> 0
A23: Opening balance | B23: $ | D23: =Loan -> 25961675 | E23: =D26 -> 25961675 | F23: =E26 -> 25961675 | G23: =F26 -> 25693347 | H23: =G26 -> 25405878 | I23: =H26 -> 25097904 | J23: =I26 -> 24767962 | K23: =J26 -> 24414485 | L23: =K26 -> 24035794 | ... N23: =M26 -> 23195447
A24: Monthly payment | B24: $ | D24: =IF(D22=1,D23*D21/Months,PMT(D21/Months,Amort_Months-Months*(D4-1-IO_Years),-D23)) -> 149495.98 | E24: =IF(E22=1,E23*E21/Months,PMT(E21/Months,Amort_Months-Months*(E4-1-IO_Years),-E23)) -> 149495.98 | F24: =IF(F22=1,F23*F21/Months,PMT(F21/Months,Amort_Months-Months*(F4-1-IO_Years),-F23)) -> 171157.31 | G24: =IF(G22=1,G23*G21/Months,PMT(G21/Months,Amort_Months-Months*(G4-1-IO_Years),-G23)) -> 171157.31 | H24: =IF(H22=1,H23*H21/Months,PMT(H21/Months,Amort_Months-Months*(H4-1-IO_Years),-H23)) -> 171157.31 | I24: =IF(I22=1,I23*I21/Months,PMT(I21/Months,Amort_Months-Months*(I4-1-IO_Years),-I23)) -> 171157.31 | J24: =IF(J22=1,J23*J21/Months,PMT(J21/Months,Amort_Months-Months*(J4-1-IO_Years),-J23)) -> 171157.31 | K24: =IF(K22=1,K23*K21/Months,PMT(K21/Months,Amort_Months-Months*(K4-1-IO_Years),-K23)) -> 171157.31 | ... N24: =IF(N22=1,N23*N21/Months,PMT(N21/Months,Amort_Months-Months*(N4-1-IO_Years),-N23)) -> 171157.31
A25: Annual debt service | B25: $ | D25: =D24*Months -> 1793951.8 | E25: =E24*Months -> 1793951.8 | F25: =F24*Months -> 2053887.8 | G25: =G24*Months -> 2053887.8 | H25: =H24*Months -> 2053887.8 | I25: =I24*Months -> 2053887.8 | J25: =J24*Months -> 2053887.8 | K25: =K24*Months -> 2053887.8 | ... N25: =N24*Months -> 2053887.8
A26: Closing balance | B26: $ | D26: =IF(D22=1,D23,FV(D21/Months,Months,D24,-D23)) -> 25961675 | E26: =IF(E22=1,E23,FV(E21/Months,Months,E24,-E23)) -> 25961675 | F26: =IF(F22=1,F23,FV(F21/Months,Months,F24,-F23)) -> 25693347 | G26: =IF(G22=1,G23,FV(G21/Months,Months,G24,-G23)) -> 25405878 | H26: =IF(H22=1,H23,FV(H21/Months,Months,H24,-H23)) -> 25097904 | I26: =IF(I22=1,I23,FV(I21/Months,Months,I24,-I23)) -> 24767962 | J26: =IF(J22=1,J23,FV(J21/Months,Months,J24,-J23)) -> 24414485 | K26: =IF(K22=1,K23,FV(K21/Months,Months,K24,-K23)) -> 24035794 | ... N26: =IF(N22=1,N23,FV(N21/Months,Months,N24,-N23)) -> 22729801
A27: Principal repaid | B27: $ | D27: =D23-D26 -> 0 | E27: =E23-E26 -> 0 | F27: =F23-F26 -> 268328.47 | G27: =G23-G26 -> 287468.61 | H27: =H23-H26 -> 307974.04 | I27: =I23-I26 -> 329942.14 | J27: =J23-J26 -> 353477.24 | K27: =K23-K26 -> 378691.13 | ... N27: =N23-N26 -> 465646.31
A28: Interest paid | B28: $ | D28: =D25-D27 -> 1793951.8 | E28: =E25-E27 -> 1793951.8 | F28: =F25-F27 -> 1785559.3 | G28: =G25-G27 -> 1766419.2 | H28: =H25-H27 -> 1745913.7 | I28: =I25-I27 -> 1723945.6 | J28: =J25-J27 -> 1700410.5 | K28: =K25-K27 -> 1675196.6 | ... N28: =N25-N27 -> 1588241.5
A29: Check: service - interest - principal | B29: $ | D29: =ABS(D25-D28-D27) -> 0 | E29: =ABS(E25-E28-E27) -> 0 | F29: =ABS(F25-F28-F27) -> 0 | G29: =ABS(G25-G28-G27) -> 0 | H29: =ABS(H25-H28-H27) -> 0 | I29: =ABS(I25-I28-I27) -> 0 | J29: =ABS(J25-J28-J27) -> 0 | K29: =ABS(K25-K28-K27) -> 0 | ... N29: =ABS(N25-N28-N27) -> 0

Sheet Covenants
A1: Covenant tests
A2: DSCR on net cash flow after reserves over annual debt service; debt yield on NOI over the opening balance. Headroom = NOI decline that would hit the cash-trap level.
A4: Year | B4: Unit | D4: 1 | E4: =D4+1 -> 2 | F4: =E4+1 -> 3 | G4: =F4+1 -> 4 | H4: =G4+1 -> 5 | I4: =H4+1 -> 6 | J4: =I4+1 -> 7 | K4: =J4+1 -> 8 | L4: =K4+1 -> 9 | ... N4: =M4+1 -> 11
A5: In hold period (1 = yes) | B5: flag | D5: =IF(D4<=Hold_Years,1,0) -> 1 | E5: =IF(E4<=Hold_Years,1,0) -> 1 | F5: =IF(F4<=Hold_Years,1,0) -> 1 | G5: =IF(G4<=Hold_Years,1,0) -> 1 | H5: =IF(H4<=Hold_Years,1,0) -> 1 | I5: =IF(I4<=Hold_Years,1,0) -> 1 | J5: =IF(J4<=Hold_Years,1,0) -> 1 | K5: =IF(K4<=Hold_Years,1,0) -> 1 | ... N5: =IF(N4<=Hold_Years,1,0) -> 0
A7: Case: status quo
A8: DSCR | B8: x | D8: =Operating!D40/Debt!D25 -> 1.4311197 | E8: =Operating!E40/Debt!E25 -> 1.4738906 | F8: =Operating!F40/Debt!F25 -> 1.325833 | G8: =Operating!G40/Debt!G25 -> 1.3654587 | H8: =Operating!H40/Debt!H25 -> 1.4062694 | I8: =Operating!I40/Debt!I25 -> 1.4483007 | J8: =Operating!J40/Debt!J25 -> 1.4915889 | K8: =Operating!K40/Debt!K25 -> 1.5361718 | ... N8: =Operating!N40/Debt!N25 -> 1.6780815
A9: DSCR headroom to cash trap | B9: % | D9: =1-DSCR_Trap/D8 -> 0.16149571 | E9: =1-DSCR_Trap/E8 -> 0.18582831 | F9: =1-DSCR_Trap/F8 -> 0.094908635 | G9: =1-DSCR_Trap/G8 -> 0.12117445 | H9: =1-DSCR_Trap/H8 -> 0.14667847 | I9: =1-DSCR_Trap/I8 -> 0.17144278 | J9: =1-DSCR_Trap/J8 -> 0.19548881 | K9: =1-DSCR_Trap/K8 -> 0.21883739 | ... N9: =1-DSCR_Trap/N8 -> 0.28489765
A10: DSCR status | D10: =IF(D8<DSCR_Default,"BREACH",IF(D8<DSCR_Trap,"CASH TRAP","OK")) -> OK | E10: =IF(E8<DSCR_Default,"BREACH",IF(E8<DSCR_Trap,"CASH TRAP","OK")) -> OK | F10: =IF(F8<DSCR_Default,"BREACH",IF(F8<DSCR_Trap,"CASH TRAP","OK")) -> OK | G10: =IF(G8<DSCR_Default,"BREACH",IF(G8<DSCR_Trap,"CASH TRAP","OK")) -> OK | H10: =IF(H8<DSCR_Default,"BREACH",IF(H8<DSCR_Trap,"CASH TRAP","OK")) -> OK | I10: =IF(I8<DSCR_Default,"BREACH",IF(I8<DSCR_Trap,"CASH TRAP","OK")) -> OK | J10: =IF(J8<DSCR_Default,"BREACH",IF(J8<DSCR_Trap,"CASH TRAP","OK")) -> OK | K10: =IF(K8<DSCR_Default,"BREACH",IF(K8<DSCR_Trap,"CASH TRAP","OK")) -> OK | ... N10: =IF(N8<DSCR_Default,"BREACH",IF(N8<DSCR_Trap,"CASH TRAP","OK")) -> OK
A11: Debt yield | B11: % | D11: =Operating!D37/Debt!D23 -> 0.1006237 | E11: =Operating!E37/Debt!E23 -> 0.10363116 | F11: =Operating!F37/Debt!F23 -> 0.10672858 | G11: =Operating!G37/Debt!G23 -> 0.11106656 | H11: =Operating!H37/Debt!H23 -> 0.11568061 | I11: =Operating!I37/Debt!I23 -> 0.12060028 | J11: =Operating!J37/Debt!J23 -> 0.12585971 | K11: =Operating!K37/Debt!K23 -> 0.13149853 | ... N11: =Operating!N37/Debt!N23 -> 0.15119636
A12: Debt-yield headroom to cash trap | B12: % | D12: =1-DY_Trap/D11 -> 0.25464872 | E12: =1-DY_Trap/E11 -> 0.27627949 | F12: =1-DY_Trap/F11 -> 0.29728287 | G12: =1-DY_Trap/G11 -> 0.32472924 | H12: =1-DY_Trap/H11 -> 0.35166317 | I12: =1-DY_Trap/I11 -> 0.37811092 | J12: =1-DY_Trap/J11 -> 0.40409844 | K12: =1-DY_Trap/K11 -> 0.42965142 | ... N12: =1-DY_Trap/N11 -> 0.50395632
A13: Debt-yield status | D13: =IF(D11<DY_Default,"BREACH",IF(D11<DY_Trap,"CASH TRAP","OK")) -> OK | E13: =IF(E11<DY_Default,"BREACH",IF(E11<DY_Trap,"CASH TRAP","OK")) -> OK | F13: =IF(F11<DY_Default,"BREACH",IF(F11<DY_Trap,"CASH TRAP","OK")) -> OK | G13: =IF(G11<DY_Default,"BREACH",IF(G11<DY_Trap,"CASH TRAP","OK")) -> OK | H13: =IF(H11<DY_Default,"BREACH",IF(H11<DY_Trap,"CASH TRAP","OK")) -> OK | I13: =IF(I11<DY_Default,"BREACH",IF(I11<DY_Trap,"CASH TRAP","OK")) -> OK | J13: =IF(J11<DY_Default,"BREACH",IF(J11<DY_Trap,"CASH TRAP","OK")) -> OK | K13: =IF(K11<DY_Default,"BREACH",IF(K11<DY_Trap,"CASH TRAP","OK")) -> OK | ... N13: =IF(N11<DY_Default,"BREACH",IF(N11<DY_Trap,"CASH TRAP","OK")) -> OK
A14: DSCR within hold (for the minimum) | B14: x | D14: =IF(D5=1,D8,"") -> 1.4311197 | E14: =IF(E5=1,E8,"") -> 1.4738906 | F14: =IF(F5=1,F8,"") -> 1.325833 | G14: =IF(G5=1,G8,"") -> 1.3654587 | H14: =IF(H5=1,H8,"") -> 1.4062694 | I14: =IF(I5=1,I8,"") -> 1.4483007 | J14: =IF(J5=1,J8,"") -> 1.4915889 | K14: =IF(K5=1,K8,"") -> 1.5361718 | ... N14: =IF(N5=1,N8,"")
A15: Debt yield within hold (for the minimum) | B15: % | D15: =IF(D5=1,D11,"") -> 0.1006237 | E15: =IF(E5=1,E11,"") -> 0.10363116 | F15: =IF(F5=1,F11,"") -> 0.10672858 | G15: =IF(G5=1,G11,"") -> 0.11106656 | H15: =IF(H5=1,H11,"") -> 0.11568061 | I15: =IF(I5=1,I11,"") -> 0.12060028 | J15: =IF(J5=1,J11,"") -> 0.12585971 | K15: =IF(K5=1,K11,"") -> 0.13149853 | ... N15: =IF(N5=1,N11,"")
A16: DSCR status within hold | D16: =IF(D5=1,D10,"") -> OK | E16: =IF(E5=1,E10,"") -> OK | F16: =IF(F5=1,F10,"") -> OK | G16: =IF(G5=1,G10,"") -> OK | H16: =IF(H5=1,H10,"") -> OK | I16: =IF(I5=1,I10,"") -> OK | J16: =IF(J5=1,J10,"") -> OK | K16: =IF(K5=1,K10,"") -> OK | ... N16: =IF(N5=1,N10,"")
A17: DY status within hold | D17: =IF(D5=1,D13,"") -> OK | E17: =IF(E5=1,E13,"") -> OK | F17: =IF(F5=1,F13,"") -> OK | G17: =IF(G5=1,G13,"") -> OK | H17: =IF(H5=1,H13,"") -> OK | I17: =IF(I5=1,I13,"") -> OK | J17: =IF(J5=1,J13,"") -> OK | K17: =IF(K5=1,K13,"") -> OK | ... N17: =IF(N5=1,N13,"")
A19: Case: retrofit
A20: DSCR | B20: x | D20: =Operating!D41/Debt!D25 -> 1.4580488 | E20: =Operating!E41/Debt!E25 -> 1.501493 | F20: =Operating!F41/Debt!F25 -> 1.3505448 | G20: =Operating!G41/Debt!G25 -> 1.3907883 | H20: =Operating!H41/Debt!H25 -> 1.4322323 | I20: =Operating!I41/Debt!I25 -> 1.4749126 | J20: =Operating!J41/Debt!J25 -> 1.5188661 | K20: =Operating!K41/Debt!K25 -> 1.564131 | ... N20: =Operating!N41/Debt!N25 -> 1.7081904
A21: DSCR headroom to cash trap | B21: % | D21: =1-DSCR_Trap/D20 -> 0.1769823 | E21: =1-DSCR_Trap/E20 -> 0.20079546 | F21: =1-DSCR_Trap/F20 -> 0.11146968 | G21: =1-DSCR_Trap/G20 -> 0.13717997 | H21: =1-DSCR_Trap/H20 -> 0.16214708 | I21: =1-DSCR_Trap/I20 -> 0.18639246 | J21: =1-DSCR_Trap/J20 -> 0.20993696 | K21: =1-DSCR_Trap/K20 -> 0.23280081 | ... N21: =1-DSCR_Trap/N20 -> 0.2975022
A22: DSCR status | D22: =IF(D20<DSCR_Default,"BREACH",IF(D20<DSCR_Trap,"CASH TRAP","OK")) -> OK | E22: =IF(E20<DSCR_Default,"BREACH",IF(E20<DSCR_Trap,"CASH TRAP","OK")) -> OK | F22: =IF(F20<DSCR_Default,"BREACH",IF(F20<DSCR_Trap,"CASH TRAP","OK")) -> OK | G22: =IF(G20<DSCR_Default,"BREACH",IF(G20<DSCR_Trap,"CASH TRAP","OK")) -> OK | H22: =IF(H20<DSCR_Default,"BREACH",IF(H20<DSCR_Trap,"CASH TRAP","OK")) -> OK | I22: =IF(I20<DSCR_Default,"BREACH",IF(I20<DSCR_Trap,"CASH TRAP","OK")) -> OK | J22: =IF(J20<DSCR_Default,"BREACH",IF(J20<DSCR_Trap,"CASH TRAP","OK")) -> OK | K22: =IF(K20<DSCR_Default,"BREACH",IF(K20<DSCR_Trap,"CASH TRAP","OK")) -> OK | ... N22: =IF(N20<DSCR_Default,"BREACH",IF(N20<DSCR_Trap,"CASH TRAP","OK")) -> OK
A23: Debt yield | B23: % | D23: =Operating!D38/Debt!D23 -> 0.1024845 | E23: =Operating!E38/Debt!E23 -> 0.10553849 | F23: =Operating!F38/Debt!F23 -> 0.10868358 | G23: =Operating!G38/Debt!G23 -> 0.11309137 | H23: =Operating!H38/Debt!H23 -> 0.11777952 | I23: =Operating!I38/Debt!I23 -> 0.12277807 | J23: =Operating!J38/Debt!J23 -> 0.12812168 | K23: =Operating!K38/Debt!K23 -> 0.13385061 | ... N23: =Operating!N38/Debt!N23 -> 0.15386242
A24: Debt-yield headroom to cash trap | B24: % | D24: =1-DY_Trap/D23 -> 0.26818201 | E24: =1-DY_Trap/E23 -> 0.28935878 | F24: =1-DY_Trap/F23 -> 0.30992339 | G24: =1-DY_Trap/G23 -> 0.33681942 | H24: =1-DY_Trap/H23 -> 0.36321699 | I24: =1-DY_Trap/I23 -> 0.38914173 | J24: =1-DY_Trap/J23 -> 0.41461898 | K24: =1-DY_Trap/K23 -> 0.43967384 | ... N24: =1-DY_Trap/N23 -> 0.51255153
A25: Debt-yield status | D25: =IF(D23<DY_Default,"BREACH",IF(D23<DY_Trap,"CASH TRAP","OK")) -> OK | E25: =IF(E23<DY_Default,"BREACH",IF(E23<DY_Trap,"CASH TRAP","OK")) -> OK | F25: =IF(F23<DY_Default,"BREACH",IF(F23<DY_Trap,"CASH TRAP","OK")) -> OK | G25: =IF(G23<DY_Default,"BREACH",IF(G23<DY_Trap,"CASH TRAP","OK")) -> OK | H25: =IF(H23<DY_Default,"BREACH",IF(H23<DY_Trap,"CASH TRAP","OK")) -> OK | I25: =IF(I23<DY_Default,"BREACH",IF(I23<DY_Trap,"CASH TRAP","OK")) -> OK | J25: =IF(J23<DY_Default,"BREACH",IF(J23<DY_Trap,"CASH TRAP","OK")) -> OK | K25: =IF(K23<DY_Default,"BREACH",IF(K23<DY_Trap,"CASH TRAP","OK")) -> OK | ... N25: =IF(N23<DY_Default,"BREACH",IF(N23<DY_Trap,"CASH TRAP","OK")) -> OK
A26: DSCR within hold (for the minimum) | B26: x | D26: =IF(D5=1,D20,"") -> 1.4580488 | E26: =IF(E5=1,E20,"") -> 1.501493 | F26: =IF(F5=1,F20,"") -> 1.3505448 | G26: =IF(G5=1,G20,"") -> 1.3907883 | H26: =IF(H5=1,H20,"") -> 1.4322323 | I26: =IF(I5=1,I20,"") -> 1.4749126 | J26: =IF(J5=1,J20,"") -> 1.5188661 | K26: =IF(K5=1,K20,"") -> 1.564131 | ... N26: =IF(N5=1,N20,"")
A27: Debt yield within hold (for the minimum) | B27: % | D27: =IF(D5=1,D23,"") -> 0.1024845 | E27: =IF(E5=1,E23,"") -> 0.10553849 | F27: =IF(F5=1,F23,"") -> 0.10868358 | G27: =IF(G5=1,G23,"") -> 0.11309137 | H27: =IF(H5=1,H23,"") -> 0.11777952 | I27: =IF(I5=1,I23,"") -> 0.12277807 | J27: =IF(J5=1,J23,"") -> 0.12812168 | K27: =IF(K5=1,K23,"") -> 0.13385061 | ... N27: =IF(N5=1,N23,"")
A28: DSCR status within hold | D28: =IF(D5=1,D22,"") -> OK | E28: =IF(E5=1,E22,"") -> OK | F28: =IF(F5=1,F22,"") -> OK | G28: =IF(G5=1,G22,"") -> OK | H28: =IF(H5=1,H22,"") -> OK | I28: =IF(I5=1,I22,"") -> OK | J28: =IF(J5=1,J22,"") -> OK | K28: =IF(K5=1,K22,"") -> OK | ... N28: =IF(N5=1,N22,"")
A29: DY status within hold | D29: =IF(D5=1,D25,"") -> OK | E29: =IF(E5=1,E25,"") -> OK | F29: =IF(F5=1,F25,"") -> OK | G29: =IF(G5=1,G25,"") -> OK | H29: =IF(H5=1,H25,"") -> OK | I29: =IF(I5=1,I25,"") -> OK | J29: =IF(J5=1,J25,"") -> OK | K29: =IF(K5=1,K25,"") -> OK | ... N29: =IF(N5=1,N25,"")
A31: Summary over the hold
A32: Minimum DSCR, SQ | B32: x | C32: =MIN(D14:N14) -> 1.325833
A33: Minimum debt yield, SQ | B33: % | C33: =MIN(D15:N15) -> 0.1006237
A34: Covenant flag-years in the hold (DSCR + debt yield), SQ | B34: count | C34: =COUNTIF(D16:N16,"<>OK")-COUNTIF(D16:N16,"")+COUNTIF(D17:N17,"<>OK")-COUNTIF(D17:N17,"") -> 0
A35: Minimum DSCR, RF | B35: x | C35: =MIN(D26:N26) -> 1.3505448
A36: Minimum debt yield, RF | B36: % | C36: =MIN(D27:N27) -> 0.1024845
A37: Covenant flag-years in the hold (DSCR + debt yield), RF | B37: count | C37: =COUNTIF(D28:N28,"<>OK")-COUNTIF(D28:N28,"")+COUNTIF(D29:N29,"<>OK")-COUNTIF(D29:N29,"") -> 0

Sheet Returns
A1: Returns
A2: Year 0 = closing. The exit is at the end of the hold on forward (next-year) NOI.
A4: Year | B4: Unit | C4: 0 | D4: 1 | E4: =D4+1 -> 2 | F4: =E4+1 -> 3 | G4: =F4+1 -> 4 | H4: =G4+1 -> 5 | I4: =H4+1 -> 6 | J4: =I4+1 -> 7 | K4: =J4+1 -> 8 | L4: =K4+1 -> 9 | ... N4: =M4+1 -> 11
A5: In hold period (1 = yes) | B5: flag | D5: =IF(D4<=Hold_Years,1,0) -> 1 | E5: =IF(E4<=Hold_Years,1,0) -> 1 | F5: =IF(F4<=Hold_Years,1,0) -> 1 | G5: =IF(G4<=Hold_Years,1,0) -> 1 | H5: =IF(H4<=Hold_Years,1,0) -> 1 | I5: =IF(I4<=Hold_Years,1,0) -> 1 | J5: =IF(J4<=Hold_Years,1,0) -> 1 | K5: =IF(K4<=Hold_Years,1,0) -> 1 | ... N5: =IF(N4<=Hold_Years,1,0) -> 0
A6: Exit year (1 = yes) | B6: flag | D6: =IF(D4=Hold_Years,1,0) -> 0 | E6: =IF(E4=Hold_Years,1,0) -> 0 | F6: =IF(F4=Hold_Years,1,0) -> 0 | G6: =IF(G4=Hold_Years,1,0) -> 0 | H6: =IF(H4=Hold_Years,1,0) -> 0 | I6: =IF(I4=Hold_Years,1,0) -> 0 | J6: =IF(J4=Hold_Years,1,0) -> 0 | K6: =IF(K4=Hold_Years,1,0) -> 0 | ... N6: =IF(N4=Hold_Years,1,0) -> 0
A8: Unlevered cash flow, status quo | B8: $ | C8: =-(Price+Closing_Costs) -> -47940000 | D8: =D5*(Operating!D40-Operating!D42)+D6*Net_Sale_SQ -> 2567359.7 | E8: =E5*(Operating!E40-Operating!E42)+E6*Net_Sale_SQ -> 2644088.7 | F8: =F5*(Operating!F40-Operating!F42)+F6*Net_Sale_SQ -> 2245707.2 | G8: =G5*(Operating!G40-Operating!G42)+G6*Net_Sale_SQ -> 2804498.9 | H8: =H5*(Operating!H40-Operating!H42)+H6*Net_Sale_SQ -> 2888319.6 | I8: =I5*(Operating!I40-Operating!I42)+I6*Net_Sale_SQ -> 2974647.1 | J8: =J5*(Operating!J40-Operating!J42)+J6*Net_Sale_SQ -> 3063556.3 | K8: =K5*(Operating!K40-Operating!K42)+K6*Net_Sale_SQ -> 3155124.5 | ... N8: =N5*(Operating!N40-Operating!N42)+N6*Net_Sale_SQ -> 0
A9: Unlevered cash flow, retrofit | B9: $ | C9: =-(Price+Closing_Costs+Retrofit_Net) -> -49934280 | D9: =D5*Operating!D41+D6*Net_Sale_RF -> 2615669.3 | E9: =E5*Operating!E41+E6*Net_Sale_RF -> 2693606 | F9: =F5*Operating!F41+F6*Net_Sale_RF -> 2773867.4 | G9: =G5*Operating!G41+G6*Net_Sale_RF -> 2856523.1 | H9: =H5*Operating!H41+H6*Net_Sale_RF -> 2941644.4 | I9: =I5*Operating!I41+I6*Net_Sale_RF -> 3029304.9 | J9: =J5*Operating!J41+J6*Net_Sale_RF -> 3119580.6 | K9: =K5*Operating!K41+K6*Net_Sale_RF -> 3212549.4 | ... N9: =N5*Operating!N41+N6*Net_Sale_RF -> 0
A10: Levered cash flow, SQ | B10: $ | C10: =C8+Loan-Loan_Fees -> -22237941 | D10: =D8-D5*Debt!D25-D6*Debt!D26 -> 773407.94 | E10: =E8-E5*Debt!E25-E6*Debt!E26 -> 850136.89 | F10: =F8-F5*Debt!F25-F6*Debt!F26 -> 191819.41 | G10: =G8-G5*Debt!G25-G6*Debt!G26 -> 750611.16 | H10: =H8-H5*Debt!H25-H6*Debt!H26 -> 834431.85 | I10: =I8-I5*Debt!I25-I6*Debt!I26 -> 920759.3 | J10: =J8-J5*Debt!J25-J6*Debt!J26 -> 1009668.5 | K10: =K8-K5*Debt!K25-K6*Debt!K26 -> 1101236.8 | ... N10: =N8-N5*Debt!N25-N6*Debt!N26 -> 0
A11: Levered cash flow, RF | B11: $ | C11: =C9+Loan-Loan_Fees -> -24232221 | D11: =D9-D5*Debt!D25-D6*Debt!D26 -> 821717.53 | E11: =E9-E5*Debt!E25-E6*Debt!E26 -> 899654.22 | F11: =F9-F5*Debt!F25-F6*Debt!F26 -> 719979.67 | G11: =G9-G5*Debt!G25-G6*Debt!G26 -> 802635.3 | H11: =H9-H5*Debt!H25-H6*Debt!H26 -> 887756.59 | I11: =I9-I5*Debt!I25-I6*Debt!I26 -> 975417.16 | J11: =J9-J5*Debt!J25-J6*Debt!J26 -> 1065692.8 | K11: =K9-K5*Debt!K25-K6*Debt!K26 -> 1158661.7 | ... N11: =N9-N5*Debt!N25-N6*Debt!N26 -> 0
A13: Sources and uses
A14: Closing costs | B14: $ | C14: =Closing_Cost_Pct*Price -> 940000
A15: Loan fees | B15: $ | C15: =Loan_Fee_Pct*Loan -> 259616.75
A16: Total uses, status quo | B16: $ | C16: =Price+Closing_Costs+Loan_Fees -> 48199617
A17: Total uses, retrofit (adds retrofit capex) | B17: $ | C17: =Uses_SQ+Retrofit_Net -> 50193897
A18: Equity, status quo | B18: $ | C18: =Uses_SQ-Loan -> 22237941
A19: Equity, retrofit | B19: $ | C19: =Uses_RF-Loan -> 24232221
A21: Exit
A22: Forward NOI at exit, SQ | B22: $ | C22: =INDEX(Operating!D37:N37,1,Hold_Years+1) -> 3507067.2
A23: Gross exit value, SQ | B23: $ | C23: =NOI_Fwd_SQ/Exit_Cap -> 60992474
A24: Net sale proceeds, SQ | B24: $ | C24: =Exit_Value_SQ*(1-Sale_Cost_Pct) -> 59772624
A25: Forward NOI at exit, RF | B25: $ | C25: =INDEX(Operating!D38:N38,1,Hold_Years+1) -> 3568907.6
A26: Gross exit value, RF | B26: $ | C26: =NOI_Fwd_RF/Exit_Cap -> 62067958
A27: Net sale proceeds, RF | B27: $ | C27: =Exit_Value_RF*(1-Sale_Cost_Pct) -> 60826599
A29: Returns
A30: Unlevered IRR, SQ | B30: % | C30: =IFERROR(IRR(C8:N8),"n/m") -> 0.076436281
A31: Levered IRR, SQ | B31: % | C31: =IFERROR(IRR(C10:N10),"n/m") -> 0.082077259
A32: Equity multiple, SQ | B32: x | C32: =SUM(D10:N10)/-C10 -> 2.0459386
A33: Check: NPV at the IRR, SQ | B33: $ | C33: =IF(ISNUMBER(Lev_IRR_SQ),NPV(Lev_IRR_SQ,D10:N10)+C10,0) -> -8.5681677e-08
A34: Unlevered IRR, RF | B34: % | C34: =IFERROR(IRR(C9:N9),"n/m") -> 0.074426157
A35: Levered IRR, RF | B35: % | C35: =IFERROR(IRR(C11:N11),"n/m") -> 0.078015475
A36: Equity multiple, RF | B36: x | C36: =SUM(D11:N11)/-C11 -> 1.9630917
A37: Check: NPV at the IRR, RF | B37: $ | C37: =IF(ISNUMBER(Lev_IRR_RF),NPV(Lev_IRR_RF,D11:N11)+C11,0) -> 2.9802322e-08
A38: Going-in cap rate (year-1 NOI, status quo) | B38: % | C38: =Operating!D37/Price -> 0.055582121
A39: Price per unit | B39: $ | C39: =Price/Units -> 313333.33

Sheet Retrofit
A1: Decarbonization retrofit
A2: Capex at closing, funded with equity. Savings are owner-paid utilities only; tenant electricity is unchanged.
A4: Capex
A5: Central heat pump plant (heat + hot water) | B5: $ | C5: =HP_Capex_Per_Unit*Units -> 1500000
A6: Envelope and air sealing | B6: $ | C6: =Envelope_Capex_Per_SF*GFA -> 225000
A7: LEDs and controls | B7: $ | C7: =LED_Capex_Per_Unit*Units -> 45000
A8: Rooftop solar | B8: $ | C8: =Solar_kWdc*Solar_Capex_Per_W*W_per_kW -> 320400
A9: Gross retrofit capex | B9: $ | C9: =HP_Capex+Envelope_Capex+LED_Capex+Solar_Capex -> 2090400
A10: Less: solar tax credit | B10: $ | C10: =Solar_ITC*Solar_Capex -> 96120
A11: Net retrofit capex | B11: $ | C11: =Retrofit_Gross-Solar_ITC_Amt -> 1994280
A13: Economics
A14: Owner utility savings, year 1 | B14: $ | C14: =Operating!D29+Operating!D30-Operating!D31-Operating!D32 -> 48309.585
A15: Simple payback on utility savings | B15: years | C15: =Retrofit_Net/Utility_Savings_Y1 -> 41.281249
A16: Payback net of the avoided boiler replacement | B16: years | C16: =(Retrofit_Net-Boiler_Replace_Cost)/Utility_Savings_Y1 -> 31.966327
A17: Exit value uplift from higher NOI | B17: $ | C17: =Exit_Value_RF-Exit_Value_SQ -> 1075484.4
A18: Levered IRR, retrofit minus status quo | B18: % | C18: =Lev_IRR_RF-Lev_IRR_SQ -> -0.0040617841
A19: Net capex per tonne avoided over measure life | B19: $/tCO2e | C19: =Retrofit_Net/(tCO2e_Avoided*Measure_Life) -> 469.43287
A21: DC Building Energy Performance Standards
A22: Retrofit meets the 20% site EUI pathway | B22: TRUE/FALSE | C22: =EUI_Reduction>=BEPS_EUI_Cut -> TRUE
A23: Maximum penalty exposure if not met (not in IRR) | B23: $ | C23: =MIN(BEPS_Penalty_Per_SF*GFA,BEPS_Penalty_Cap) -> 1500000

Sheet Scenarios
A1: Stress cases
A2: Post-closing stress: the loan is held at its base-case size (Loan_Override is set to the base loan by the stress engine) and operations, the exit and the retrofit underperform. SOFR shocks only bite when the floating option (Debt_Option = 2) is selected.
A4: Case currently shown (Inputs!Case_Select) | B4: =CHOOSE(Case_Select,"Base","Downside","Severe") -> Base
A5: Loan amount | B5: =Loan -> 25961675
A6: Minimum DSCR, status quo | B6: =Min_DSCR_SQ -> 1.325833
A7: Minimum DSCR, retrofit | B7: =Min_DSCR_RF -> 1.3505448
A8: Minimum debt yield, status quo | B8: =Min_DY_SQ -> 0.1006237
A9: Covenant flag-years, status quo | B9: =Trap_Years_SQ -> 0
A10: Levered IRR, status quo | B10: =Lev_IRR_SQ -> 0.082077259
A11: Levered IRR, retrofit | B11: =Lev_IRR_RF -> 0.078015475
A12: Equity multiple, retrofit | B12: =Equity_Multiple_RF -> 1.9630917
A13: Exit value, retrofit | B13: =Exit_Value_RF -> 62067958
A14: Retrofit simple payback | B14: =Payback_Years -> 41.281249
A15: Site EUI after retrofit | B15: =EUI_RF -> 37.094778
A17: Snapshot of all three cases (Python engine at build time; set Case_Select to reproduce any column live)
A18: Metric | B18: Base | C18: Downside | D18: Severe
A19: Loan amount | B19: 25961675 | C19: 25961675 | D19: 25961675
A20: Minimum DSCR, status quo | B20: 1.325833 | C20: 1.2448959 | D20: 1.0861032
A21: Minimum DSCR, retrofit | B21: 1.3505448 | C21: 1.267733 | D21: 1.1147341
A22: Minimum debt yield, status quo | B22: 0.1006237 | C22: 0.097648872 | D22: 0.092540602
A23: Covenant flag-years, status quo | B23: 0 | C23: 0 | D23: 8
A24: Levered IRR, status quo | B24: 0.082077259 | C24: 0.02581933 | D24: -0.062282158
A25: Levered IRR, retrofit | B25: 0.078015475 | C25: 0.022347018 | D25: -0.061210459
A26: Equity multiple, retrofit | B26: 1.9630917 | C26: 1.2181576 | D26: 0.5713611
A27: Exit value, retrofit | B27: 62067958 | C27: 47211689 | D27: 34575900
A28: Retrofit simple payback | B28: 41.281249 | C28: 54.110084 | D28: 72.396956
A29: Site EUI after retrofit | B29: 37.094778 | C29: 37.697555 | D29: 38.481166
A31: One factor at a time from the base case: levered IRR, retrofit
A32: Lever | B32: Value | C32: Change from base
A33: Rent growth -1.5 pts | B33: 0.036301056 | C33: -0.041714419
A34: Vacancy +5 pts | B34: 0.059053352 | C34: -0.018962123
A35: Floating rate, SOFR +200 bp | B35: 0.061690695 | C35: -0.01632478
A36: Exit cap +50 bp | B36: 0.065714571 | C36: -0.012300904
A37: Expense growth +1 pt | B37: 0.072407259 | C37: -0.0056082154
A38: Heat pump capex +50% | B38: 0.074277008 | C38: -0.0037384665
A39: Heat pump COP 2.0 | B39: 0.077075067 | C39: -0.00094040714
A40: No solar tax credit | B40: 0.077528662 | C40: -0.00048681285
A42: One factor at a time from the base case: minimum DSCR, status quo
A43: Lever | B43: Value | C43: Change from base
A44: Floating rate, SOFR +200 bp | B44: 1.1080527 | C44: -0.21778026
...

Sheet Checks
A1: Checks
A2: Each check returns TRUE when it passes.
A4: Sources = uses, status quo | C4: =ABS(Loan+Equity_SQ-Uses_SQ)<=Tolerance -> TRUE
A5: Sources = uses, retrofit | C5: =ABS(Loan+Equity_RF-Uses_RF)<=Tolerance -> TRUE
A6: Loan within LTV, DSCR and debt-yield limits | C6: =OR(Loan_Override>0,AND(Loan<=Max_Loan_LTV+Tolerance,Loan<=Max_Loan_DSCR+Tolerance,Loan<=Max_Loan_DY+Tolerance)) -> TRUE
A7: Loan balance never negative | C7: =MIN(Debt!D26:N26)>=0 -> TRUE
A8: Debt service = interest + principal every year | C8: =MAX(Debt!D29:N29)<=Tolerance -> TRUE
A9: End-use shares sum to 100% | C9: =ABS(Share_Heat_Gas+Share_DHW_Gas+Share_Common_Elec+Share_Tenant_Elec-1)<=Tolerance -> TRUE
A10: Baseline energy by end use reconciles to site energy | C10: =ABS(Gas_SQ_MMBtu+(Common_kWh+Tenant_kWh)/kWh_per_MMBtu-Site_MMBtu_Base)<=Tolerance -> TRUE
A11: Solar does not exceed owner electricity use | C11: =Solar_kWh<=Owner_Gross_RF_kWh -> TRUE
A12: NPV at the levered IRR is zero, status quo | C12: =ABS(Lev_NPV_At_IRR_SQ)<=Tolerance*Equity_SQ -> TRUE
A13: NPV at the levered IRR is zero, retrofit | C13: =ABS(Lev_NPV_At_IRR_RF)<=Tolerance*Equity_RF -> TRUE
A14: Hold period fits the model columns | C14: =AND(Hold_Years>=1,Hold_Years<=COUNT(Operating!D4:N4)-1) -> TRUE
A16: All checks pass | C16: =AND(Check_SU_SQ,Check_SU_RF,Check_Loan_Limits,Check_Balance,Check_Debt_Service,Check_Shares,Check_Energy,Check_Solar,Check_IRR_SQ,Check_IRR_RF,Check_Hold) -> TRUE
