Workbook
Name All_Checks: Checks!$C$15
Name Asset_Mgmt: Inputs!$C$24
Name Avg_Draw: Inputs!$C$21
Name Avg_DSCR_Op: Ratios!$C$20
Name Avg_DSCR_P50: Ratios!$C$16
Name Avg_DSCR_P90: Ratios!$C$18
Name BESS_Capex: Capex_SU!$C$10
Name BESS_Capex_Base: Capex_SU!$C$7
Name BESS_Capex_Per_kWh: Inputs!$C$18
Name BESS_FOM_Pct: Inputs!$C$23
Name BESS_Hours: Inputs!$C$8
Name BESS_Life: Inputs!$C$10
Name BESS_MW: Inputs!$C$7
Name BESS_MWh: Capex_SU!$C$6
Name Capex_Overrun: Inputs!$C$56
Name Capex_Per_tCO2e: Returns!$C$25
Name Case_Select: Inputs!$C$60
Name CF_P50: Inputs!$C$11
Name Check_Debt_PV: Checks!$C$5
Name Check_DSCR_P50: Checks!$C$9
Name Check_DSCR_P90: Checks!$C$10
Name Check_Gearing: Checks!$C$11
Name Check_IRR: Checks!$C$13
Name Check_No_Negative: Checks!$C$7
Name Check_Parity: Checks!$C$8
Name Check_Repaid: Checks!$C$6
Name Check_SU: Checks!$C$4
Name Check_Tenor: Checks!$C$12
Name Constr_Years: Inputs!$C$20
Name Curtailment: Inputs!$C$12
Name Debt: Debt_Sculpt!$C$8
Name Debt_Capacity_Gearing: Debt_Sculpt!$C$7
Name Debt_Capacity_Sculpt: Debt_Sculpt!$C$6
Name Debt_Spread: Inputs!$C$46
Name Default_Years: Ratios!$C$25
Name Degradation: Inputs!$C$13
Name Dep_Basis: Tax!$C$5
Name Dev_Costs: Capex_SU!$C$12
Name DSCR_Default_PF: Inputs!$C$52
Name DSCR_Lockup: Inputs!$C$51
Name DSCR_P50_Target: Inputs!$C$49
Name DSCR_P90_Target: Inputs!$C$50
Name DSRA: Capex_SU!$C$16
Name DSRA_Months: Inputs!$C$55
Name Equipment_Capex: Capex_SU!$C$11
Name Equity: Capex_SU!$C$22
Name Equity_Hurdle: Inputs!$C$44
Name Equity_IRR: Returns!$C$13
Name Equity_IRR_AT: Returns!$C$15
Name Equity_Multiple: Returns!$C$16
Name Equity_NPV_At_IRR: Returns!$C$17
Name Equity_NPV_At_IRR_AT: Returns!$C$18
Name Fees: Capex_SU!$C$15
Name Gearing: Debt_Sculpt!$C$10
Name Gen_Case_Z: Inputs!$C$58
Name Gen_Sigma_1yr: Inputs!$C$14
Name Gen_Y1_P50: Returns!$C$21
Name Grid_CO2e_lb_MWh: Inputs!$C$59
Name Hours_Per_Year: Inputs!$C$61
Name IDC: Capex_SU!$C$14

Sheet Cover
A1: Solar + storage project financing
A2: 200 MWac solar + 100 MW / 400 MWh battery, West Texas (ERCOT), illustrative. Sculpted senior debt.
A4: Status | B4: Illustrative underwriting case built on public benchmarks. Not a real property, transaction or offer; no proprietary data.
A5: Model checks | B5: =IF(All_Checks,"All checks pass","CHECK FAILURES - see Checks tab") -> All checks pass
A6: Code version | B6: uncommitted
A7: Inputs fingerprint | B7: 358aa6d73eb6
A8: Data retrieved | B8: 2026-10-15
A9: Colour convention | B9: Blue on yellow = input (Inputs tab only). Green = formula reading another tab or a named input. Black = formula on the same tab.
A10: Periods | B10: Annual. Year 1 starts at closing.
A12: Tabs
A13: Summary | B13: Key outputs
A14: Inputs | B14: Every assumption with its tag and source id
A15: Sources | B15: Citations, URLs and retrieval dates
A16: Capex_SU | B16: Capital costs, tax-credit proceeds, sources and uses
A17: Generation | B17: P50, P90 and operating-case output with degradation and curtailment
A18: Revenue | B18: PPA, merchant tail and battery toll
A19: Opex | B19: Solar and battery O&M and asset management
A20: CFADS | B20: Cash flow available for debt service: sizing (P50, P90) and operating case
A21: Debt_Sculpt | B21: Closed-form sculpted debt sizing and the repayment schedule
A22: Ratios | B22: DSCR by year (P50, P90, operating), LLCR and PLCR
A23: Tax | B23: MACRS depreciation and tax for a sponsor that can use losses
A24: Returns | B24: Project and equity cash flows, pre- and after-tax IRRs, avoided emissions
... A26: Checks | B26: Integrity checks; the Cover shows whether all pass

Sheet Summary
A1: Summary
A3: Project capex | B3: =Project_Capex -> 425984000 | C3: $
A4: Senior debt | B4: =Debt -> 2.2240406e+08 | C4: $
A5: Gearing (debt / project capex) | B5: =Gearing -> 0.52209486 | C5: %
A6: Tax-credit proceeds | B6: =ITC_Proceeds -> 113049600 | C6: $
A7: Sponsor equity | B7: =Equity -> 1.1400223e+08 | C7: $
A8: Coupon | B8: =Rate -> 0.0696 | C8: %
A9: Minimum DSCR, P50 | B9: =Min_DSCR_P50 -> 1.35 | C9: x
A10: Minimum DSCR, P90 | B10: =Min_DSCR_P90 -> 1.2000632 | C10: x
A11: Minimum DSCR, operating case | B11: =Min_DSCR_Op -> 1.35 | C11: x
A12: LLCR | B12: =LLCR -> 1.35 | C12: x
A13: PLCR | B13: =PLCR -> 1.4601346 | C13: x
A14: Project IRR, pre-tax | B14: =Project_IRR -> 0.074437961 | C14: %
A15: Equity IRR, pre-tax | B15: =Equity_IRR -> 0.062792016 | C15: %
A16: Equity IRR, after tax | B16: =Equity_IRR_AT -> 0.081350134 | C16: %
A17: Generation, year 1 (P50) | B17: =Gen_Y1_P50 -> 535483.03 | C17: MWh
A18: Net capacity factor, year 1 | B18: =Net_CF_Y1 -> 0.305641 | C18: %
A19: Grid emissions displaced, year 1 | B19: =tCO2e_Avoided_Y1 -> 188070.74 | C19: tCO2e

Sheet Inputs
A1: Inputs
A2: Every assumption in the model, once. Tag: Sourced = read from the cited public source; Estimated = analyst assumption anchored to a source; Illustrative = deal definition; Definition = unit conversion.
I3: Stress cases: the live value in column C follows Case_Select (1 = Base, 2 = Downside, 3 = Severe)
A4: Section | B4: Input | C4: Value | D4: Unit | E4: Tag | F4: Source id | G4: Note | I4: Base | J4: Downside | K4: Severe
A5: Project | B5: Solar capacity (AC) | C5: 200 | D5: MWac | E5: Illustrative | F5: asset
A6: Project | B6: Inverter loading ratio (DC/AC) | C6: 1.34 | D6: ratio | E6: Sourced | F6: atb_2024b_pv
A7: Project | B7: Battery power | C7: 100 | D7: MW | E7: Illustrative | F7: asset
A8: Project | B8: Battery duration | C8: 4 | D8: hours | E8: Illustrative | F8: asset
A9: Project | B9: Solar useful life | C9: 30 | D9: years | E9: Sourced | F9: atb_2024b_pv | G9: Model columns cover 30 operating years
A10: Project | B10: Battery useful life | C10: 15 | D10: years | E10: Sourced | F10: atb_2024b_bess | G10: No repowering assumed; battery cash flows stop after year 15
A11: Generation | B11: Solar capacity factor, first year (ATB resource class 2) | C11: 0.329 | D11: % (AC) | E11: Sourced | F11: atb_2024b_pv | G11: West Texas mapped to class 2 (GHI 5.5-5.75); the mapping is a judgement
A12: Generation | B12: Curtailment loss | C12: 0.071 | D12: % of output | E12: Sourced | F12: lbnl_uss_2025 | G12: ERCOT ISO-wide 2024; mostly West Texas
A13: Generation | B13: Annual degradation | C13: 0.007 | D13: %/yr | E13: Sourced | F13: atb_2024b_pv
A14: Generation | B14: One-year generation uncertainty (1 sigma) | C14: 0.06 | D14: % of P50 | E14: Estimated | F14: analyst | G14: Inter-annual resource plus modelling uncertainty; EIA does not publish P-values
A15: Generation | B15: Normal quantile for P90 | C15: 1.2816 | D15: z | E15: Definition | F15: normal_quantiles
A16: Generation | B16: Normal quantile for P99 | C16: 2.3263 | D16: z | E16: Definition | F16: normal_quantiles
A17: Capital costs | B17: Solar installed cost (ERCOT | C17: 1.38 | D17: $/Wac | E17: Sourced | F17: lbnl_uss_2025
A18: Capital costs | B18: Battery installed cost (4-hour | C18: 334 | D18: $/kWh | E18: Sourced | F18: nlr_bess_2025
A19: Capital costs | B19: Development | C19: 0.04 | D19: % of equipment capex | E19: Estimated | F19: analyst
A20: Capital costs | B20: Construction period | C20: 1 | D20: years | E20: Illustrative | F20: asset
A21: Capital costs | B21: Average share of debt drawn during construction | C21: 0.5 | D21: % | E21: Estimated | F21: analyst
A22: Operating costs | B22: Solar fixed O&M (all-in) | C22: 22 | D22: $/kWac-yr | E22: Sourced | F22: atb_2024b_pv | G22: ATB 2023 value; includes insurance, property tax and land per ATB scope
A23: Operating costs | B23: Battery fixed O&M incl. augmentation | C23: 0.025 | D23: % of battery capex/yr | E23: Sourced | F23: atb_2024b_bess
A24: Operating costs | B24: Asset management and admin | C24: 500000 | D24: $/yr | E24: Estimated | F24: analyst
A25: Operating costs | B25: Opex escalation | C25: 0.025 | D25: %/yr | E25: Estimated | F25: analyst
A26: Revenue | B26: Solar PPA price (as generated | C26: 51 | D26: $/MWh | E26: Estimated | F26: lbnl_uss_2025 | G26: Solved (rounded) for an 8% after-tax sponsor equity IRR at benchmark capex and today's rates; ~27% above the top of the 2024 IQR ($22-40)
A27: Revenue | B27: PPA escalator | C27: 0 | D27: %/yr | E27: Estimated | F27: analyst
A28: Revenue | B28: PPA term | C28: 20 | D28: years | E28: Estimated | F28: analyst
A29: Revenue | B29: Merchant solar price after the PPA (ERCOT | C29: 24 | D29: $/MWh | E29: Sourced | F29: lbnl_uss_2025 | G29: ERCOT solar market value 2024 (chart reading)
A30: Revenue | B30: Merchant price escalation | C30: 0.02 | D30: %/yr | E30: Estimated | F30: analyst
A31: Revenue | B31: Battery tolling payment | C31: 12 | D31: $/kW-month | E31: Illustrative | F31: analyst | G31: ERCOT has no capacity market; the toll stands in for capacity and ancillary value
A32: Revenue | B32: Tolling term | C32: 15 | D32: years | E32: Illustrative | F32: asset
A33: Tax credits | B33: Solar investment tax credit | C33: 0.3 | D33: % of solar capex | E33: Illustrative | F33: analyst | G33: Assumes construction began in time under post-2025 federal rules; stressed to 0
A34: Tax credits | B34: Storage investment tax credit | C34: 0.3 | D34: % of battery capex | E34: Illustrative | F34: analyst
A35: Tax credits | B35: Credit transfer price | C35: 0.92 | D35: $ per $1 of credit | E35: Estimated | F35: analyst
A36: Tax | B36: Federal corporate income tax rate | C36: 0.21 | D36: % | E36: Sourced | F36: irc_tax | G36: Texas has no corporate income tax; the margin tax is ignored
A37: Tax | B37: 5-year MACRS | C37: 0.2 | D37: % of basis | E37: Sourced | F37: irs_pub946
A38: Tax | B38: 5-year MACRS | C38: 0.32 | D38: % of basis | E38: Sourced | F38: irs_pub946
A39: Tax | B39: 5-year MACRS | C39: 0.192 | D39: % of basis | E39: Sourced | F39: irs_pub946
A40: Tax | B40: 5-year MACRS | C40: 0.1152 | D40: % of basis | E40: Sourced | F40: irs_pub946
...

Sheet Sources
A1: Sources
A3: Source id | B3: Citation | C3: URL | D3: Retrieved
A4: egrid2022 | B4: EPA eGRID2022 Summary Tables: total output emission rates, RFC East (RFCE) 660.3 lb CO2e/MWh; ERCOT All (ERCT) 774.3 lb CO2e/MWh; U.S. 827.5 lb CO2e/MWh | C4: https://www.epa.gov/system/files/documents/2024-01/egrid2022_summary_tables.pdf | D4: 2026-10-15
A5: fred_dgs10 | B5: FRED DGS10, 10-year Treasury constant maturity, 5.21% on 2026-10-13 (fetched with quantlab.data.sources.extra.fred_series) | C5: https://fred.stlouisfed.org/series/DGS10 | D5: 2026-10-15
A6: lbnl_uss_2025 | B6: Berkeley Lab, Utility-Scale Solar 2025 Edition (2024 data): installed cost $1.61/Wac national, $1.38/Wac ERCOT (slide 34); median O&M ~$11/kWac-yr; levelized PPA average $29/MWh, IQR $22-40 (slide 11); ERCOT solar curtailment 7.1% (slide 57); ERCOT solar market value $24/MWh vs $29 flat block, read from the slide-61 chart | C6: https://emp.lbl.gov/sites/default/files/2025-10/Utility%20Scale%20Solar%202025%20Edition%20Slides.pdf | D6: 2026-10-15
A7: atb_2024b_pv | B7: NREL/NLR Annual Technology Baseline 2024b, Utility-Scale PV: CAPEX $1,430/kWac (2022), fixed O&M $22/kWac-yr (2023), ILR 1.34, degradation 0.7%/yr, 30-yr life, class 1-5 capacity factors 34.0%-28.3% | C7: https://atb.nlr.gov/electricity/2024b/utility-scale_pv | D7: 2026-10-15
A8: atb_2024b_bess | B8: NREL/NLR Annual Technology Baseline 2024b, Utility-Scale Battery Storage: fixed O&M 2.5% of capex per year (includes augmentation), 85% round-trip efficiency, 15-year life | C8: https://atb.nlr.gov/electricity/2024b/utility-scale_battery_storage | D8: 2026-10-15
A9: nlr_bess_2025 | B9: Cole, Ramasamy & Turan, Cost Projections for Utility-Scale Battery Storage: 2025 Update (NREL/TP-6A40-93281): 2024 cost of a 4-hour system $334/kWh (2024$) = $241/kWh energy + $372/kW power | C9: https://docs.nlr.gov/docs/fy25osti/93281.pdf | D9: 2026-10-15
A10: asset | B10: Illustrative asset definition for this model (unit mix, size, deal terms). Not a real property or transaction. | D10: 2026-10-15
A11: analyst | B11: Analyst estimate, stated in the input note. Not taken from a single published figure; treat as an assumption to stress. | D11: 2026-10-15
A12: definition | B12: Unit conversion or definition (e.g. 12 months per year, 3,412.14 Btu per kWh, 2,204.62 lb per metric ton). | D12: 2026-10-15
A13: normal_quantiles | B13: Standard normal quantiles: z(0.90) = 1.2816, z(0.99) = 2.3263, used to turn a one-year generation uncertainty into P90 and P99 output | D13: 2026-10-15
A14: irc_tax | B14: Internal Revenue Code: 21% corporate rate (IRC 11(b)); depreciable basis reduced by 50% of an investment credit (IRC 50(c)(3)) | C14: https://www.law.cornell.edu/uscode/text/26/11 | D14: 2026-10-15
A15: irs_pub946 | B15: IRS Publication 946, Table A-1: 5-year property, half-year convention: 20.00%, 32.00%, 19.20%, 11.52%, 11.52%, 5.76% | C15: https://www.irs.gov/publications/p946 | D15: 2026-10-15

Sheet Capex_SU
A1: Capital costs, sources and uses
A2: At financial close (year 0).
A4: Size
A5: Solar capacity (DC) | B5: MWdc | C5: =PV_MWac*ILR -> 268
A6: Battery energy | B6: MWh | C6: =BESS_MW*BESS_Hours -> 400
A7: Battery cost at benchmark (O&M basis) | B7: $ | C7: =BESS_MWh*kWh_per_MWh*BESS_Capex_Per_kWh -> 133600000
A8: Uses
A9: Solar equipment and installation | B9: $ | C9: =PV_MWac*kW_per_MW*W_per_kW*PV_Capex_Per_Wac*(1+Capex_Overrun) -> 276000000
A10: Battery equipment and installation | B10: $ | C10: =BESS_Capex_Base*(1+Capex_Overrun) -> 133600000
A11: Equipment capex | B11: $ | C11: =PV_Capex+BESS_Capex -> 409600000
A12: Development, owner and interconnection | B12: $ | C12: =Owner_Dev_Pct*Equipment_Capex -> 16384000
A13: Project capex | B13: $ | C13: =Equipment_Capex+Dev_Costs -> 425984000
A14: Interest during construction | B14: $ | C14: =Debt*Rate*Constr_Years*Avg_Draw -> 7739661.1
A15: Upfront financing fees | B15: $ | C15: =Upfront_Fee*Debt -> 3336060.8
A16: Debt service reserve funding | B16: $ | C16: =DSRA_Months/Months*INDEX(R_Debt_Service,1,1) -> 12396161
A17: Total uses | B17: $ | C17: =Project_Capex+IDC+Fees+DSRA -> 4.4945588e+08
A19: Sources
A20: Senior debt | B20: $ | C20: =Debt -> 2.2240406e+08
A21: Tax-credit transfer proceeds | B21: $ | C21: =(ITC_PV*PV_Capex+ITC_BESS*BESS_Capex)*ITC_Transfer_Price -> 113049600
A22: Sponsor equity | B22: $ | C22: =Total_Uses-Debt-ITC_Proceeds -> 1.1400223e+08
A23: Total sources | B23: $ | C23: =Debt+ITC_Proceeds+Equity -> 4.4945588e+08

Sheet Generation
A1: Generation
A2: MWh delivered after curtailment. P90/P99 are one-year exceedance levels: P50 x (1 - z x sigma).
A4: Year | B4: Unit | D4: 1 | E4: =D4+1 -> 2 | F4: =E4+1 -> 3 | G4: =F4+1 -> 4 | H4: =G4+1 -> 5 | I4: =H4+1 -> 6 | J4: =I4+1 -> 7 | K4: =J4+1 -> 8 | L4: =K4+1 -> 9 | ... AG4: =AF4+1 -> 30
A5: P90 / P50 | B5: ratio | C5: =1-Z_P90*Gen_Sigma_1yr -> 0.923104
A6: P99 / P50 | B6: ratio | C6: =1-Z_P99*Gen_Sigma_1yr -> 0.860422
A7: Operating case / P50 | B7: ratio | C7: =1-Gen_Case_Z*Gen_Sigma_1yr -> 1
A9: Solar operating (1 = yes) | B9: flag | D9: =IF(D4<=PV_Life,1,0) -> 1 | E9: =IF(E4<=PV_Life,1,0) -> 1 | F9: =IF(F4<=PV_Life,1,0) -> 1 | G9: =IF(G4<=PV_Life,1,0) -> 1 | H9: =IF(H4<=PV_Life,1,0) -> 1 | I9: =IF(I4<=PV_Life,1,0) -> 1 | J9: =IF(J4<=PV_Life,1,0) -> 1 | K9: =IF(K4<=PV_Life,1,0) -> 1 | ... AG9: =IF(AG4<=PV_Life,1,0) -> 1
A10: Battery operating (1 = yes) | B10: flag | D10: =IF(D4<=BESS_Life,1,0) -> 1 | E10: =IF(E4<=BESS_Life,1,0) -> 1 | F10: =IF(F4<=BESS_Life,1,0) -> 1 | G10: =IF(G4<=BESS_Life,1,0) -> 1 | H10: =IF(H4<=BESS_Life,1,0) -> 1 | I10: =IF(I4<=BESS_Life,1,0) -> 1 | J10: =IF(J4<=BESS_Life,1,0) -> 1 | K10: =IF(K4<=BESS_Life,1,0) -> 1 | ... AG10: =IF(AG4<=BESS_Life,1,0) -> 0
A11: Degradation index | B11: index | D11: =(1-Degradation)^(D4-1) -> 1 | E11: =(1-Degradation)^(E4-1) -> 0.993 | F11: =(1-Degradation)^(F4-1) -> 0.986049 | G11: =(1-Degradation)^(G4-1) -> 0.97914666 | H11: =(1-Degradation)^(H4-1) -> 0.97229263 | I11: =(1-Degradation)^(I4-1) -> 0.96548658 | J11: =(1-Degradation)^(J4-1) -> 0.95872818 | K11: =(1-Degradation)^(K4-1) -> 0.95201708 | ... AG11: =(1-Degradation)^(AG4-1) -> 0.81569576
A12: Generation, P50 | B12: MWh | D12: =PV_MWac*Hours_Per_Year*CF_P50*(1-Curtailment)*D11*D9 -> 535483.03 | E12: =PV_MWac*Hours_Per_Year*CF_P50*(1-Curtailment)*E11*E9 -> 531734.65 | F12: =PV_MWac*Hours_Per_Year*CF_P50*(1-Curtailment)*F11*F9 -> 528012.51 | G12: =PV_MWac*Hours_Per_Year*CF_P50*(1-Curtailment)*G11*G9 -> 524316.42 | H12: =PV_MWac*Hours_Per_Year*CF_P50*(1-Curtailment)*H11*H9 -> 520646.21 | I12: =PV_MWac*Hours_Per_Year*CF_P50*(1-Curtailment)*I11*I9 -> 517001.68 | J12: =PV_MWac*Hours_Per_Year*CF_P50*(1-Curtailment)*J11*J9 -> 513382.67 | K12: =PV_MWac*Hours_Per_Year*CF_P50*(1-Curtailment)*K11*K9 -> 509788.99 | ... AG12: =PV_MWac*Hours_Per_Year*CF_P50*(1-Curtailment)*AG11*AG9 -> 436791.24
A13: Generation, P90 | B13: MWh | D13: =D12*P90_Factor -> 494306.53 | E13: =E12*P90_Factor -> 490846.38 | F13: =F12*P90_Factor -> 487410.46 | G13: =G12*P90_Factor -> 483998.59 | H13: =H12*P90_Factor -> 480610.6 | I13: =I12*P90_Factor -> 477246.32 | J13: =J12*P90_Factor -> 473905.6 | K13: =K12*P90_Factor -> 470588.26 | ... AG13: =AG12*P90_Factor -> 403203.74
A14: Generation, operating case | B14: MWh | D14: =D12*Op_Gen_Factor -> 535483.03 | E14: =E12*Op_Gen_Factor -> 531734.65 | F14: =F12*Op_Gen_Factor -> 528012.51 | G14: =G12*Op_Gen_Factor -> 524316.42 | H14: =H12*Op_Gen_Factor -> 520646.21 | I14: =I12*Op_Gen_Factor -> 517001.68 | J14: =J12*Op_Gen_Factor -> 513382.67 | K14: =K12*Op_Gen_Factor -> 509788.99 | ... AG14: =AG12*Op_Gen_Factor -> 436791.24

Sheet Revenue
A1: Revenue
A2: As-generated PPA, then merchant at the ERCOT solar market value; battery tolling for the battery's life.
A4: Year | B4: Unit | D4: 1 | E4: =D4+1 -> 2 | F4: =E4+1 -> 3 | G4: =F4+1 -> 4 | H4: =G4+1 -> 5 | I4: =H4+1 -> 6 | J4: =I4+1 -> 7 | K4: =J4+1 -> 8 | L4: =K4+1 -> 9 | ... AG4: =AF4+1 -> 30
A5: PPA in force (1 = yes) | B5: flag | D5: =IF(D4<=PPA_Term,1,0) -> 1 | E5: =IF(E4<=PPA_Term,1,0) -> 1 | F5: =IF(F4<=PPA_Term,1,0) -> 1 | G5: =IF(G4<=PPA_Term,1,0) -> 1 | H5: =IF(H4<=PPA_Term,1,0) -> 1 | I5: =IF(I4<=PPA_Term,1,0) -> 1 | J5: =IF(J4<=PPA_Term,1,0) -> 1 | K5: =IF(K4<=PPA_Term,1,0) -> 1 | ... AG5: =IF(AG4<=PPA_Term,1,0) -> 0
A6: Toll in force (1 = yes) | B6: flag | D6: =IF(AND(D4<=Toll_Term,D4<=BESS_Life),1,0) -> 1 | E6: =IF(AND(E4<=Toll_Term,E4<=BESS_Life),1,0) -> 1 | F6: =IF(AND(F4<=Toll_Term,F4<=BESS_Life),1,0) -> 1 | G6: =IF(AND(G4<=Toll_Term,G4<=BESS_Life),1,0) -> 1 | H6: =IF(AND(H4<=Toll_Term,H4<=BESS_Life),1,0) -> 1 | I6: =IF(AND(I4<=Toll_Term,I4<=BESS_Life),1,0) -> 1 | J6: =IF(AND(J4<=Toll_Term,J4<=BESS_Life),1,0) -> 1 | K6: =IF(AND(K4<=Toll_Term,K4<=BESS_Life),1,0) -> 1 | ... AG6: =IF(AND(AG4<=Toll_Term,AG4<=BESS_Life),1,0) -> 0
A7: PPA price | B7: $/MWh | D7: =PPA_Price*(1+PPA_Escalator)^(D4-1) -> 51 | E7: =PPA_Price*(1+PPA_Escalator)^(E4-1) -> 51 | F7: =PPA_Price*(1+PPA_Escalator)^(F4-1) -> 51 | G7: =PPA_Price*(1+PPA_Escalator)^(G4-1) -> 51 | H7: =PPA_Price*(1+PPA_Escalator)^(H4-1) -> 51 | I7: =PPA_Price*(1+PPA_Escalator)^(I4-1) -> 51 | J7: =PPA_Price*(1+PPA_Escalator)^(J4-1) -> 51 | K7: =PPA_Price*(1+PPA_Escalator)^(K4-1) -> 51 | ... AG7: =PPA_Price*(1+PPA_Escalator)^(AG4-1) -> 51
A8: Merchant price, base | B8: $/MWh | D8: =Merchant_Price*(1+Merchant_Escalation)^(D4-1) -> 24 | E8: =Merchant_Price*(1+Merchant_Escalation)^(E4-1) -> 24.48 | F8: =Merchant_Price*(1+Merchant_Escalation)^(F4-1) -> 24.9696 | G8: =Merchant_Price*(1+Merchant_Escalation)^(G4-1) -> 25.468992 | H8: =Merchant_Price*(1+Merchant_Escalation)^(H4-1) -> 25.978372 | I8: =Merchant_Price*(1+Merchant_Escalation)^(I4-1) -> 26.497939 | J8: =Merchant_Price*(1+Merchant_Escalation)^(J4-1) -> 27.027898 | K8: =Merchant_Price*(1+Merchant_Escalation)^(K4-1) -> 27.568456 | ... AG8: =Merchant_Price*(1+Merchant_Escalation)^(AG4-1) -> 42.620273
A9: Realised solar price, sizing case | B9: $/MWh | D9: =D5*D7+(1-D5)*D8 -> 51 | E9: =E5*E7+(1-E5)*E8 -> 51 | F9: =F5*F7+(1-F5)*F8 -> 51 | G9: =G5*G7+(1-G5)*G8 -> 51 | H9: =H5*H7+(1-H5)*H8 -> 51 | I9: =I5*I7+(1-I5)*I8 -> 51 | J9: =J5*J7+(1-J5)*J8 -> 51 | K9: =K5*K7+(1-K5)*K8 -> 51 | ... AG9: =AG5*AG7+(1-AG5)*AG8 -> 42.620273
A10: Realised solar price, operating case | B10: $/MWh | D10: =D5*D7+(1-D5)*D8*(1+Merchant_Shock) -> 51 | E10: =E5*E7+(1-E5)*E8*(1+Merchant_Shock) -> 51 | F10: =F5*F7+(1-F5)*F8*(1+Merchant_Shock) -> 51 | G10: =G5*G7+(1-G5)*G8*(1+Merchant_Shock) -> 51 | H10: =H5*H7+(1-H5)*H8*(1+Merchant_Shock) -> 51 | I10: =I5*I7+(1-I5)*I8*(1+Merchant_Shock) -> 51 | J10: =J5*J7+(1-J5)*J8*(1+Merchant_Shock) -> 51 | K10: =K5*K7+(1-K5)*K8*(1+Merchant_Shock) -> 51 | ... AG10: =AG5*AG7+(1-AG5)*AG8*(1+Merchant_Shock) -> 42.620273
A12: Solar revenue, P50 | B12: $ | D12: =Generation!D12*D9 -> 27309635 | E12: =Generation!E12*E9 -> 27118467 | F12: =Generation!F12*F9 -> 26928638 | G12: =Generation!G12*G9 -> 26740137 | H12: =Generation!H12*H9 -> 26552956 | I12: =Generation!I12*I9 -> 26367086 | J12: =Generation!J12*J9 -> 26182516 | K12: =Generation!K12*K9 -> 25999239 | ... AG12: =Generation!AG12*AG9 -> 18616162
A13: Solar revenue, P90 | B13: $ | D13: =Generation!D13*D9 -> 25209633 | E13: =Generation!E13*E9 -> 25033166 | F13: =Generation!F13*F9 -> 24857933 | G13: =Generation!G13*G9 -> 24683928 | H13: =Generation!H13*H9 -> 24511140 | I13: =Generation!I13*I9 -> 24339562 | J13: =Generation!J13*J9 -> 24169185 | K13: =Generation!K13*K9 -> 24000001 | ... AG13: =Generation!AG13*AG9 -> 17184653
A14: Solar revenue, operating case | B14: $ | D14: =Generation!D14*D10 -> 27309635 | E14: =Generation!E14*E10 -> 27118467 | F14: =Generation!F14*F10 -> 26928638 | G14: =Generation!G14*G10 -> 26740137 | H14: =Generation!H14*H10 -> 26552956 | I14: =Generation!I14*I10 -> 26367086 | J14: =Generation!J14*J10 -> 26182516 | K14: =Generation!K14*K10 -> 25999239 | ... AG14: =Generation!AG14*AG10 -> 18616162
A15: Battery toll revenue | B15: $ | D15: =Toll_Price*BESS_MW*kW_per_MW*Months*D6 -> 14400000 | E15: =Toll_Price*BESS_MW*kW_per_MW*Months*E6 -> 14400000 | F15: =Toll_Price*BESS_MW*kW_per_MW*Months*F6 -> 14400000 | G15: =Toll_Price*BESS_MW*kW_per_MW*Months*G6 -> 14400000 | H15: =Toll_Price*BESS_MW*kW_per_MW*Months*H6 -> 14400000 | I15: =Toll_Price*BESS_MW*kW_per_MW*Months*I6 -> 14400000 | J15: =Toll_Price*BESS_MW*kW_per_MW*Months*J6 -> 14400000 | K15: =Toll_Price*BESS_MW*kW_per_MW*Months*K6 -> 14400000 | ... AG15: =Toll_Price*BESS_MW*kW_per_MW*Months*AG6 -> 0

Sheet Opex
A1: Operating costs
A2: Solar O&M is ATB's all-in figure; battery O&M includes augmentation.
A4: Year | B4: Unit | D4: 1 | E4: =D4+1 -> 2 | F4: =E4+1 -> 3 | G4: =F4+1 -> 4 | H4: =G4+1 -> 5 | I4: =H4+1 -> 6 | J4: =I4+1 -> 7 | K4: =J4+1 -> 8 | L4: =K4+1 -> 9 | ... AG4: =AF4+1 -> 30
A5: Escalation index | B5: index | D5: =(1+Opex_Escalation)^(D4-1) -> 1 | E5: =(1+Opex_Escalation)^(E4-1) -> 1.025 | F5: =(1+Opex_Escalation)^(F4-1) -> 1.050625 | G5: =(1+Opex_Escalation)^(G4-1) -> 1.0768906 | H5: =(1+Opex_Escalation)^(H4-1) -> 1.1038129 | I5: =(1+Opex_Escalation)^(I4-1) -> 1.1314082 | J5: =(1+Opex_Escalation)^(J4-1) -> 1.1596934 | K5: =(1+Opex_Escalation)^(K4-1) -> 1.1886858 | ... AG5: =(1+Opex_Escalation)^(AG4-1) -> 2.0464074
A6: Solar O&M | B6: $ | D6: =PV_FOM_Per_kWac*PV_MWac*kW_per_MW*D5*Generation!D9 -> 4400000 | E6: =PV_FOM_Per_kWac*PV_MWac*kW_per_MW*E5*Generation!E9 -> 4510000 | F6: =PV_FOM_Per_kWac*PV_MWac*kW_per_MW*F5*Generation!F9 -> 4622750 | G6: =PV_FOM_Per_kWac*PV_MWac*kW_per_MW*G5*Generation!G9 -> 4738318.7 | H6: =PV_FOM_Per_kWac*PV_MWac*kW_per_MW*H5*Generation!H9 -> 4856776.7 | I6: =PV_FOM_Per_kWac*PV_MWac*kW_per_MW*I5*Generation!I9 -> 4978196.1 | J6: =PV_FOM_Per_kWac*PV_MWac*kW_per_MW*J5*Generation!J9 -> 5102651 | K6: =PV_FOM_Per_kWac*PV_MWac*kW_per_MW*K5*Generation!K9 -> 5230217.3 | ... AG6: =PV_FOM_Per_kWac*PV_MWac*kW_per_MW*AG5*Generation!AG9 -> 9004192.5
A7: Battery O&M incl. augmentation | B7: $ | D7: =BESS_FOM_Pct*BESS_Capex_Base*D5*Generation!D10 -> 3340000 | E7: =BESS_FOM_Pct*BESS_Capex_Base*E5*Generation!E10 -> 3423500 | F7: =BESS_FOM_Pct*BESS_Capex_Base*F5*Generation!F10 -> 3509087.5 | G7: =BESS_FOM_Pct*BESS_Capex_Base*G5*Generation!G10 -> 3596814.7 | H7: =BESS_FOM_Pct*BESS_Capex_Base*H5*Generation!H10 -> 3686735.1 | I7: =BESS_FOM_Pct*BESS_Capex_Base*I5*Generation!I10 -> 3778903.4 | J7: =BESS_FOM_Pct*BESS_Capex_Base*J5*Generation!J10 -> 3873376 | K7: =BESS_FOM_Pct*BESS_Capex_Base*K5*Generation!K10 -> 3970210.4 | ... AG7: =BESS_FOM_Pct*BESS_Capex_Base*AG5*Generation!AG10 -> 0
A8: Asset management | B8: $ | D8: =Asset_Mgmt*D5*Generation!D9 -> 500000 | E8: =Asset_Mgmt*E5*Generation!E9 -> 512500 | F8: =Asset_Mgmt*F5*Generation!F9 -> 525312.5 | G8: =Asset_Mgmt*G5*Generation!G9 -> 538445.31 | H8: =Asset_Mgmt*H5*Generation!H9 -> 551906.45 | I8: =Asset_Mgmt*I5*Generation!I9 -> 565704.11 | J8: =Asset_Mgmt*J5*Generation!J9 -> 579846.71 | K8: =Asset_Mgmt*K5*Generation!K9 -> 594342.88 | ... AG8: =Asset_Mgmt*AG5*Generation!AG9 -> 1023203.7
A9: Total operating costs | B9: $ | D9: =D6+D7+D8 -> 8240000 | E9: =E6+E7+E8 -> 8446000 | F9: =F6+F7+F8 -> 8657150 | G9: =G6+G7+G8 -> 8873578.7 | H9: =H6+H7+H8 -> 9095418.2 | I9: =I6+I7+I8 -> 9322803.7 | J9: =J6+J7+J8 -> 9555873.8 | K9: =K6+K7+K8 -> 9794770.6 | ... AG9: =AG6+AG7+AG8 -> 10027396

Sheet CFADS
A1: Cash flow available for debt service
A2: Pre-tax (the project is a pass-through entity). Sizing cases use base prices; the operating case carries the stress inputs. After the PPA the plant is idled rather than run at a loss, so merchant-year cash flow is floored at zero.
A4: Year | B4: Unit | D4: 1 | E4: =D4+1 -> 2 | F4: =E4+1 -> 3 | G4: =F4+1 -> 4 | H4: =G4+1 -> 5 | I4: =H4+1 -> 6 | J4: =I4+1 -> 7 | K4: =J4+1 -> 8 | L4: =K4+1 -> 9 | ... AG4: =AF4+1 -> 30
A5: CFADS, P50 (sizing) | B5: $ | D5: =IF(Revenue!D5=1,Revenue!D12+Revenue!D15-Opex!D9,MAX(Revenue!D12+Revenue!D15-Opex!D9,0)) -> 33469635 | E5: =IF(Revenue!E5=1,Revenue!E12+Revenue!E15-Opex!E9,MAX(Revenue!E12+Revenue!E15-Opex!E9,0)) -> 33072467 | F5: =IF(Revenue!F5=1,Revenue!F12+Revenue!F15-Opex!F9,MAX(Revenue!F12+Revenue!F15-Opex!F9,0)) -> 32671488 | G5: =IF(Revenue!G5=1,Revenue!G12+Revenue!G15-Opex!G9,MAX(Revenue!G12+Revenue!G15-Opex!G9,0)) -> 32266559 | H5: =IF(Revenue!H5=1,Revenue!H12+Revenue!H15-Opex!H9,MAX(Revenue!H12+Revenue!H15-Opex!H9,0)) -> 31857538 | I5: =IF(Revenue!I5=1,Revenue!I12+Revenue!I15-Opex!I9,MAX(Revenue!I12+Revenue!I15-Opex!I9,0)) -> 31444282 | J5: =IF(Revenue!J5=1,Revenue!J12+Revenue!J15-Opex!J9,MAX(Revenue!J12+Revenue!J15-Opex!J9,0)) -> 31026642 | K5: =IF(Revenue!K5=1,Revenue!K12+Revenue!K15-Opex!K9,MAX(Revenue!K12+Revenue!K15-Opex!K9,0)) -> 30604468 | ... AG5: =IF(Revenue!AG5=1,Revenue!AG12+Revenue!AG15-Opex!AG9,MAX(Revenue!AG12+Revenue!AG15-Opex!AG9,0)) -> 8588765.5
A6: CFADS, P90 (sizing) | B6: $ | D6: =IF(Revenue!D5=1,Revenue!D13+Revenue!D15-Opex!D9,MAX(Revenue!D13+Revenue!D15-Opex!D9,0)) -> 31369633 | E6: =IF(Revenue!E5=1,Revenue!E13+Revenue!E15-Opex!E9,MAX(Revenue!E13+Revenue!E15-Opex!E9,0)) -> 30987166 | F6: =IF(Revenue!F5=1,Revenue!F13+Revenue!F15-Opex!F9,MAX(Revenue!F13+Revenue!F15-Opex!F9,0)) -> 30600783 | G6: =IF(Revenue!G5=1,Revenue!G13+Revenue!G15-Opex!G9,MAX(Revenue!G13+Revenue!G15-Opex!G9,0)) -> 30210349 | H6: =IF(Revenue!H5=1,Revenue!H13+Revenue!H15-Opex!H9,MAX(Revenue!H13+Revenue!H15-Opex!H9,0)) -> 29815722 | I6: =IF(Revenue!I5=1,Revenue!I13+Revenue!I15-Opex!I9,MAX(Revenue!I13+Revenue!I15-Opex!I9,0)) -> 29416759 | J6: =IF(Revenue!J5=1,Revenue!J13+Revenue!J15-Opex!J9,MAX(Revenue!J13+Revenue!J15-Opex!J9,0)) -> 29013312 | K6: =IF(Revenue!K5=1,Revenue!K13+Revenue!K15-Opex!K9,MAX(Revenue!K13+Revenue!K15-Opex!K9,0)) -> 28605231 | ... AG6: =IF(Revenue!AG5=1,Revenue!AG13+Revenue!AG15-Opex!AG9,MAX(Revenue!AG13+Revenue!AG15-Opex!AG9,0)) -> 7157257.1
A7: CFADS, operating case | B7: $ | D7: =IF(Revenue!D5=1,Revenue!D14+Revenue!D15-Opex!D9,MAX(Revenue!D14+Revenue!D15-Opex!D9,0)) -> 33469635 | E7: =IF(Revenue!E5=1,Revenue!E14+Revenue!E15-Opex!E9,MAX(Revenue!E14+Revenue!E15-Opex!E9,0)) -> 33072467 | F7: =IF(Revenue!F5=1,Revenue!F14+Revenue!F15-Opex!F9,MAX(Revenue!F14+Revenue!F15-Opex!F9,0)) -> 32671488 | G7: =IF(Revenue!G5=1,Revenue!G14+Revenue!G15-Opex!G9,MAX(Revenue!G14+Revenue!G15-Opex!G9,0)) -> 32266559 | H7: =IF(Revenue!H5=1,Revenue!H14+Revenue!H15-Opex!H9,MAX(Revenue!H14+Revenue!H15-Opex!H9,0)) -> 31857538 | I7: =IF(Revenue!I5=1,Revenue!I14+Revenue!I15-Opex!I9,MAX(Revenue!I14+Revenue!I15-Opex!I9,0)) -> 31444282 | J7: =IF(Revenue!J5=1,Revenue!J14+Revenue!J15-Opex!J9,MAX(Revenue!J14+Revenue!J15-Opex!J9,0)) -> 31026642 | K7: =IF(Revenue!K5=1,Revenue!K14+Revenue!K15-Opex!K9,MAX(Revenue!K14+Revenue!K15-Opex!K9,0)) -> 30604468 | ... AG7: =IF(Revenue!AG5=1,Revenue!AG14+Revenue!AG15-Opex!AG9,MAX(Revenue!AG14+Revenue!AG15-Opex!AG9,0)) -> 8588765.5

Sheet Debt_Sculpt
A1: Debt sizing and sculpting
A2: Closed form: debt = NPV of target service at the coupon, capped by gearing; no circular references.
A4: Year | B4: Unit | D4: 1 | E4: =D4+1 -> 2 | F4: =E4+1 -> 3 | G4: =F4+1 -> 4 | H4: =G4+1 -> 5 | I4: =H4+1 -> 6 | J4: =I4+1 -> 7 | K4: =J4+1 -> 8 | L4: =K4+1 -> 9 | ... AG4: =AF4+1 -> 30
A5: Coupon (Treasury + spread + shock) | B5: % | C5: =UST_10Y+Debt_Spread+Rate_Shock -> 0.0696
A6: Debt supported by target service (NPV) | B6: $ | C6: =NPV(Rate,D13:AG13) -> 2.2240406e+08
A7: Gearing cap | B7: $ | C7: =Max_Gearing*Project_Capex -> 298188800
A8: Senior debt | B8: $ | C8: =MIN(Debt_Capacity_Sculpt,Debt_Capacity_Gearing) -> 2.2240406e+08
A9: Service scale (1 = DSCR targets bind) | B9: ratio | C9: =Debt/Debt_Capacity_Sculpt -> 1
A10: Debt / project capex | B10: % | C10: =Debt/Project_Capex -> 0.52209486
A12: Within tenor (1 = yes) | B12: flag | D12: =IF(D4<=Tenor,1,0) -> 1 | E12: =IF(E4<=Tenor,1,0) -> 1 | F12: =IF(F4<=Tenor,1,0) -> 1 | G12: =IF(G4<=Tenor,1,0) -> 1 | H12: =IF(H4<=Tenor,1,0) -> 1 | I12: =IF(I4<=Tenor,1,0) -> 1 | J12: =IF(J4<=Tenor,1,0) -> 1 | K12: =IF(K4<=Tenor,1,0) -> 1 | ... AG12: =IF(AG4<=Tenor,1,0) -> 0
A13: Target service = MIN(P50/1.35x, P90/1.00x) | B13: $ | D13: =MIN(CFADS!D5/DSCR_P50_Target,CFADS!D6/DSCR_P90_Target)*D12 -> 24792322 | E13: =MIN(CFADS!E5/DSCR_P50_Target,CFADS!E6/DSCR_P90_Target)*E12 -> 24498124 | F13: =MIN(CFADS!F5/DSCR_P50_Target,CFADS!F6/DSCR_P90_Target)*F12 -> 24201102 | G13: =MIN(CFADS!G5/DSCR_P50_Target,CFADS!G6/DSCR_P90_Target)*G12 -> 23901155 | H13: =MIN(CFADS!H5/DSCR_P50_Target,CFADS!H6/DSCR_P90_Target)*H12 -> 23598176 | I13: =MIN(CFADS!I5/DSCR_P50_Target,CFADS!I6/DSCR_P90_Target)*I12 -> 23292061 | J13: =MIN(CFADS!J5/DSCR_P50_Target,CFADS!J6/DSCR_P90_Target)*J12 -> 22982698 | K13: =MIN(CFADS!K5/DSCR_P50_Target,CFADS!K6/DSCR_P90_Target)*K12 -> 22669976 | ... AG13: =MIN(CFADS!AG5/DSCR_P50_Target,CFADS!AG6/DSCR_P90_Target)*AG12 -> 0
A14: Scheduled debt service | B14: $ | D14: =D13*Sculpt_Scale -> 24792322 | E14: =E13*Sculpt_Scale -> 24498124 | F14: =F13*Sculpt_Scale -> 24201102 | G14: =G13*Sculpt_Scale -> 23901155 | H14: =H13*Sculpt_Scale -> 23598176 | I14: =I13*Sculpt_Scale -> 23292061 | J14: =J13*Sculpt_Scale -> 22982698 | K14: =K13*Sculpt_Scale -> 22669976 | ... AG14: =AG13*Sculpt_Scale -> 0
A15: Opening balance | B15: $ | D15: =Debt -> 2.2240406e+08 | E15: =D18 -> 2.1309106e+08 | F15: =E18 -> 2.0342407e+08 | G15: =F18 -> 1.9338128e+08 | H15: =G18 -> 1.8293946e+08 | I15: =H18 -> 1.7207388e+08 | J15: =I18 -> 1.6075816e+08 | K15: =J18 -> 1.4896423e+08 | L15: =K18 -> 1.3666216e+08 | ... AG15: =AF18 -> 1.2221086e-06
A16: Interest | B16: $ | D16: =D15*Rate -> 15479322 | E16: =E15*Rate -> 14831137 | F16: =F15*Rate -> 14158315 | G16: =G15*Rate -> 13459337 | H16: =H15*Rate -> 12732587 | I16: =I15*Rate -> 11976342 | J16: =J15*Rate -> 11188768 | K16: =K15*Rate -> 10367910 | ... AG16: =AG15*Rate -> 8.5058759e-08
A17: Principal | B17: $ | D17: =D14-D16 -> 9312999.7 | E17: =E14-E16 -> 9666986.4 | F17: =F14-F16 -> 10042787 | G17: =G14-G16 -> 10441817 | H17: =H14-H16 -> 10865590 | I17: =I14-I16 -> 11315719 | J17: =J14-J16 -> 11793930 | K17: =K14-K16 -> 12302066 | ... AG17: =AG14-AG16 -> -8.5058759e-08
A18: Closing balance | B18: $ | D18: =D15-D17 -> 2.1309106e+08 | E18: =E15-E17 -> 2.0342407e+08 | F18: =F15-F17 -> 1.9338128e+08 | G18: =G15-G17 -> 1.8293946e+08 | H18: =H15-H17 -> 1.7207388e+08 | I18: =I15-I17 -> 1.6075816e+08 | J18: =J15-J17 -> 1.4896423e+08 | K18: =K15-K17 -> 1.3666216e+08 | ... AG18: =AG15-AG17 -> 1.3071674e-06

Sheet Ratios
A1: Coverage ratios
A2: DSCR shown inside the tenor only. LLCR = NPV of P50 CFADS over the tenor / debt; PLCR = over the project life.
A4: Year | B4: Unit | D4: 1 | E4: =D4+1 -> 2 | F4: =E4+1 -> 3 | G4: =F4+1 -> 4 | H4: =G4+1 -> 5 | I4: =H4+1 -> 6 | J4: =I4+1 -> 7 | K4: =J4+1 -> 8 | L4: =K4+1 -> 9 | ... AG4: =AF4+1 -> 30
A5: DSCR, P50 | B5: x | D5: =IF(Debt_Sculpt!D12=1,CFADS!D5/Debt_Sculpt!D14,"") -> 1.35 | E5: =IF(Debt_Sculpt!E12=1,CFADS!E5/Debt_Sculpt!E14,"") -> 1.35 | F5: =IF(Debt_Sculpt!F12=1,CFADS!F5/Debt_Sculpt!F14,"") -> 1.35 | G5: =IF(Debt_Sculpt!G12=1,CFADS!G5/Debt_Sculpt!G14,"") -> 1.35 | H5: =IF(Debt_Sculpt!H12=1,CFADS!H5/Debt_Sculpt!H14,"") -> 1.35 | I5: =IF(Debt_Sculpt!I12=1,CFADS!I5/Debt_Sculpt!I14,"") -> 1.35 | J5: =IF(Debt_Sculpt!J12=1,CFADS!J5/Debt_Sculpt!J14,"") -> 1.35 | K5: =IF(Debt_Sculpt!K12=1,CFADS!K5/Debt_Sculpt!K14,"") -> 1.35 | ... AG5: =IF(Debt_Sculpt!AG12=1,CFADS!AG5/Debt_Sculpt!AG14,"")
A6: DSCR, P90 | B6: x | D6: =IF(Debt_Sculpt!D12=1,CFADS!D6/Debt_Sculpt!D14,"") -> 1.2652963 | E6: =IF(Debt_Sculpt!E12=1,CFADS!E6/Debt_Sculpt!E14,"") -> 1.2648791 | F6: =IF(Debt_Sculpt!F12=1,CFADS!F6/Debt_Sculpt!F14,"") -> 1.2644376 | G6: =IF(Debt_Sculpt!G12=1,CFADS!G6/Debt_Sculpt!G14,"") -> 1.2639703 | H6: =IF(Debt_Sculpt!H12=1,CFADS!H6/Debt_Sculpt!H14,"") -> 1.2634757 | I6: =IF(Debt_Sculpt!I12=1,CFADS!I6/Debt_Sculpt!I14,"") -> 1.2629522 | J6: =IF(Debt_Sculpt!J12=1,CFADS!J6/Debt_Sculpt!J14,"") -> 1.262398 | K6: =IF(Debt_Sculpt!K12=1,CFADS!K6/Debt_Sculpt!K14,"") -> 1.2618112 | ... AG6: =IF(Debt_Sculpt!AG12=1,CFADS!AG6/Debt_Sculpt!AG14,"")
A7: DSCR, Op | B7: x | D7: =IF(Debt_Sculpt!D12=1,CFADS!D7/Debt_Sculpt!D14,"") -> 1.35 | E7: =IF(Debt_Sculpt!E12=1,CFADS!E7/Debt_Sculpt!E14,"") -> 1.35 | F7: =IF(Debt_Sculpt!F12=1,CFADS!F7/Debt_Sculpt!F14,"") -> 1.35 | G7: =IF(Debt_Sculpt!G12=1,CFADS!G7/Debt_Sculpt!G14,"") -> 1.35 | H7: =IF(Debt_Sculpt!H12=1,CFADS!H7/Debt_Sculpt!H14,"") -> 1.35 | I7: =IF(Debt_Sculpt!I12=1,CFADS!I7/Debt_Sculpt!I14,"") -> 1.35 | J7: =IF(Debt_Sculpt!J12=1,CFADS!J7/Debt_Sculpt!J14,"") -> 1.35 | K7: =IF(Debt_Sculpt!K12=1,CFADS!K7/Debt_Sculpt!K14,"") -> 1.35 | ... AG7: =IF(Debt_Sculpt!AG12=1,CFADS!AG7/Debt_Sculpt!AG14,"")
A8: P50 CFADS inside the tenor | B8: $ | D8: =CFADS!D5*Debt_Sculpt!D12 -> 33469635 | E8: =CFADS!E5*Debt_Sculpt!E12 -> 33072467 | F8: =CFADS!F5*Debt_Sculpt!F12 -> 32671488 | G8: =CFADS!G5*Debt_Sculpt!G12 -> 32266559 | H8: =CFADS!H5*Debt_Sculpt!H12 -> 31857538 | I8: =CFADS!I5*Debt_Sculpt!I12 -> 31444282 | J8: =CFADS!J5*Debt_Sculpt!J12 -> 31026642 | K8: =CFADS!K5*Debt_Sculpt!K12 -> 30604468 | ... AG8: =CFADS!AG5*Debt_Sculpt!AG12 -> 0
A9: Operating CFADS inside the tenor | B9: $ | D9: =CFADS!D7*Debt_Sculpt!D12 -> 33469635 | E9: =CFADS!E7*Debt_Sculpt!E12 -> 33072467 | F9: =CFADS!F7*Debt_Sculpt!F12 -> 32671488 | G9: =CFADS!G7*Debt_Sculpt!G12 -> 32266559 | H9: =CFADS!H7*Debt_Sculpt!H12 -> 31857538 | I9: =CFADS!I7*Debt_Sculpt!I12 -> 31444282 | J9: =CFADS!J7*Debt_Sculpt!J12 -> 31026642 | K9: =CFADS!K7*Debt_Sculpt!K12 -> 30604468 | ... AG9: =CFADS!AG7*Debt_Sculpt!AG12 -> 0
A10: Check: target - scheduled service / scale | B10: $ | D10: =MIN(CFADS!D5/DSCR_P50_Target,CFADS!D6/DSCR_P90_Target)*Debt_Sculpt!D12-Debt_Sculpt!D14/Sculpt_Scale -> 0 | E10: =MIN(CFADS!E5/DSCR_P50_Target,CFADS!E6/DSCR_P90_Target)*Debt_Sculpt!E12-Debt_Sculpt!E14/Sculpt_Scale -> 0 | F10: =MIN(CFADS!F5/DSCR_P50_Target,CFADS!F6/DSCR_P90_Target)*Debt_Sculpt!F12-Debt_Sculpt!F14/Sculpt_Scale -> 0 | G10: =MIN(CFADS!G5/DSCR_P50_Target,CFADS!G6/DSCR_P90_Target)*Debt_Sculpt!G12-Debt_Sculpt!G14/Sculpt_Scale -> 0 | H10: =MIN(CFADS!H5/DSCR_P50_Target,CFADS!H6/DSCR_P90_Target)*Debt_Sculpt!H12-Debt_Sculpt!H14/Sculpt_Scale -> 0 | I10: =MIN(CFADS!I5/DSCR_P50_Target,CFADS!I6/DSCR_P90_Target)*Debt_Sculpt!I12-Debt_Sculpt!I14/Sculpt_Scale -> 0 | J10: =MIN(CFADS!J5/DSCR_P50_Target,CFADS!J6/DSCR_P90_Target)*Debt_Sculpt!J12-Debt_Sculpt!J14/Sculpt_Scale -> 0 | K10: =MIN(CFADS!K5/DSCR_P50_Target,CFADS!K6/DSCR_P90_Target)*Debt_Sculpt!K12-Debt_Sculpt!K14/Sculpt_Scale -> 0 | ... AG10: =MIN(CFADS!AG5/DSCR_P50_Target,CFADS!AG6/DSCR_P90_Target)*Debt_Sculpt!AG12-Debt_Sculpt!AG14/Sculpt_Scale -> 0
A11: Absolute parity error | B11: $ | D11: =ABS(D10) -> 0 | E11: =ABS(E10) -> 0 | F11: =ABS(F10) -> 0 | G11: =ABS(G10) -> 0 | H11: =ABS(H10) -> 0 | I11: =ABS(I10) -> 0 | J11: =ABS(J10) -> 0 | K11: =ABS(K10) -> 0 | ... AG11: =ABS(AG10) -> 0
A12: Below lock-up (1 = yes) | B12: flag | D12: =IF(Debt_Sculpt!D12=1,IF(CFADS!D7/Debt_Sculpt!D14<DSCR_Lockup,1,0),0) -> 0 | E12: =IF(Debt_Sculpt!E12=1,IF(CFADS!E7/Debt_Sculpt!E14<DSCR_Lockup,1,0),0) -> 0 | F12: =IF(Debt_Sculpt!F12=1,IF(CFADS!F7/Debt_Sculpt!F14<DSCR_Lockup,1,0),0) -> 0 | G12: =IF(Debt_Sculpt!G12=1,IF(CFADS!G7/Debt_Sculpt!G14<DSCR_Lockup,1,0),0) -> 0 | H12: =IF(Debt_Sculpt!H12=1,IF(CFADS!H7/Debt_Sculpt!H14<DSCR_Lockup,1,0),0) -> 0 | I12: =IF(Debt_Sculpt!I12=1,IF(CFADS!I7/Debt_Sculpt!I14<DSCR_Lockup,1,0),0) -> 0 | J12: =IF(Debt_Sculpt!J12=1,IF(CFADS!J7/Debt_Sculpt!J14<DSCR_Lockup,1,0),0) -> 0 | K12: =IF(Debt_Sculpt!K12=1,IF(CFADS!K7/Debt_Sculpt!K14<DSCR_Lockup,1,0),0) -> 0 | ... AG12: =IF(Debt_Sculpt!AG12=1,IF(CFADS!AG7/Debt_Sculpt!AG14<DSCR_Lockup,1,0),0) -> 0
A13: Below default trigger (1 = yes) | B13: flag | D13: =IF(Debt_Sculpt!D12=1,IF(CFADS!D7/Debt_Sculpt!D14<DSCR_Default_PF,1,0),0) -> 0 | E13: =IF(Debt_Sculpt!E12=1,IF(CFADS!E7/Debt_Sculpt!E14<DSCR_Default_PF,1,0),0) -> 0 | F13: =IF(Debt_Sculpt!F12=1,IF(CFADS!F7/Debt_Sculpt!F14<DSCR_Default_PF,1,0),0) -> 0 | G13: =IF(Debt_Sculpt!G12=1,IF(CFADS!G7/Debt_Sculpt!G14<DSCR_Default_PF,1,0),0) -> 0 | H13: =IF(Debt_Sculpt!H12=1,IF(CFADS!H7/Debt_Sculpt!H14<DSCR_Default_PF,1,0),0) -> 0 | I13: =IF(Debt_Sculpt!I12=1,IF(CFADS!I7/Debt_Sculpt!I14<DSCR_Default_PF,1,0),0) -> 0 | J13: =IF(Debt_Sculpt!J12=1,IF(CFADS!J7/Debt_Sculpt!J14<DSCR_Default_PF,1,0),0) -> 0 | K13: =IF(Debt_Sculpt!K12=1,IF(CFADS!K7/Debt_Sculpt!K14<DSCR_Default_PF,1,0),0) -> 0 | ... AG13: =IF(Debt_Sculpt!AG12=1,IF(CFADS!AG7/Debt_Sculpt!AG14<DSCR_Default_PF,1,0),0) -> 0
A15: Minimum DSCR, P50 | B15: x | C15: =MIN(D5:AG5) -> 1.35
A16: Average DSCR, P50 | B16: x | C16: =AVERAGE(D5:AG5) -> 1.35
A17: Minimum DSCR, P90 | B17: x | C17: =MIN(D6:AG6) -> 1.2000632
A18: Average DSCR, P90 | B18: x | C18: =AVERAGE(D6:AG6) -> 1.2515823
A19: Minimum DSCR, Op | B19: x | C19: =MIN(D7:AG7) -> 1.35
A20: Average DSCR, Op | B20: x | C20: =AVERAGE(D7:AG7) -> 1.35
A21: LLCR (P50) | B21: x | C21: =NPV(Rate,D8:AG8)/Debt -> 1.35
A22: PLCR (P50) | B22: x | C22: =NPV(Rate,CFADS!D5:AG5)/Debt -> 1.4601346
A23: LLCR, operating case | B23: x | C23: =NPV(Rate,D9:AG9)/Debt -> 1.35
A24: Years below the distribution lock-up (operating case) | B24: years | C24: =SUM(D12:AG12) -> 0
A25: Years below the default trigger (operating case) | B25: years | C25: =SUM(D13:AG13) -> 0

Sheet Tax
A1: Tax
A2: Sponsor-level tax on operating CFADS less interest and MACRS depreciation; losses are used as they arise (a tax-efficient sponsor). Texas has no corporate income tax.
A4: Year | B4: Unit | D4: 1 | E4: =D4+1 -> 2 | F4: =E4+1 -> 3 | G4: =F4+1 -> 4 | H4: =G4+1 -> 5 | I4: =H4+1 -> 6 | J4: =I4+1 -> 7 | K4: =J4+1 -> 8 | L4: =K4+1 -> 9 | ... AG4: =AF4+1 -> 30
A5: Depreciable basis (less 50% of credits) | B5: $ | C5: =Project_Capex-ITC_Basis_Reduction*(ITC_PV*PV_Capex+ITC_BESS*BESS_Capex) -> 364544000
A7: MACRS depreciation | B7: $ | D7: =IF(D4<=COUNT(MACRS_Table),Dep_Basis*INDEX(MACRS_Table,D4),0) -> 72908800 | E7: =IF(E4<=COUNT(MACRS_Table),Dep_Basis*INDEX(MACRS_Table,E4),0) -> 116654080 | F7: =IF(F4<=COUNT(MACRS_Table),Dep_Basis*INDEX(MACRS_Table,F4),0) -> 69992448 | G7: =IF(G4<=COUNT(MACRS_Table),Dep_Basis*INDEX(MACRS_Table,G4),0) -> 41995469 | H7: =IF(H4<=COUNT(MACRS_Table),Dep_Basis*INDEX(MACRS_Table,H4),0) -> 41995469 | I7: =IF(I4<=COUNT(MACRS_Table),Dep_Basis*INDEX(MACRS_Table,I4),0) -> 20997734 | J7: =IF(J4<=COUNT(MACRS_Table),Dep_Basis*INDEX(MACRS_Table,J4),0) -> 0 | K7: =IF(K4<=COUNT(MACRS_Table),Dep_Basis*INDEX(MACRS_Table,K4),0) -> 0 | ... AG7: =IF(AG4<=COUNT(MACRS_Table),Dep_Basis*INDEX(MACRS_Table,AG4),0) -> 0
A8: Taxable income | B8: $ | D8: =CFADS!D7-Debt_Sculpt!D16-D7 -> -54918488 | E8: =CFADS!E7-Debt_Sculpt!E16-E7 -> -98412750 | F8: =CFADS!F7-Debt_Sculpt!F16-F7 -> -51479275 | G8: =CFADS!G7-Debt_Sculpt!G16-G7 -> -23188247 | H8: =CFADS!H7-Debt_Sculpt!H16-H7 -> -22870517 | I8: =CFADS!I7-Debt_Sculpt!I16-I7 -> -1529794 | J8: =CFADS!J7-Debt_Sculpt!J16-J7 -> 19837875 | K8: =CFADS!K7-Debt_Sculpt!K16-K7 -> 20236558 | ... AG8: =CFADS!AG7-Debt_Sculpt!AG16-AG7 -> 8588765.5
A9: Tax (negative = benefit used by the sponsor) | B9: $ | D9: =Tax_Rate*D8 -> -11532882 | E9: =Tax_Rate*E8 -> -20666678 | F9: =Tax_Rate*F8 -> -10810648 | G9: =Tax_Rate*G8 -> -4869531.9 | H9: =Tax_Rate*H8 -> -4802808.6 | I9: =Tax_Rate*I8 -> -321256.74 | J9: =Tax_Rate*J8 -> 4165953.7 | K9: =Tax_Rate*K8 -> 4249677.2 | ... AG9: =Tax_Rate*AG8 -> 1803640.8

Sheet Returns
A1: Returns
A2: Year 0 = financial close. Equity receives operating CFADS less scheduled debt service, and the DSRA back at maturity.
A4: Year | B4: Unit | C4: 0 | D4: 1 | E4: =D4+1 -> 2 | F4: =E4+1 -> 3 | G4: =F4+1 -> 4 | H4: =G4+1 -> 5 | I4: =H4+1 -> 6 | J4: =I4+1 -> 7 | K4: =J4+1 -> 8 | L4: =K4+1 -> 9 | ... AG4: =AF4+1 -> 30
A5: DSRA released at maturity | B5: $ | D5: =IF(D4=Tenor,DSRA,0) -> 0 | E5: =IF(E4=Tenor,DSRA,0) -> 0 | F5: =IF(F4=Tenor,DSRA,0) -> 0 | G5: =IF(G4=Tenor,DSRA,0) -> 0 | H5: =IF(H4=Tenor,DSRA,0) -> 0 | I5: =IF(I4=Tenor,DSRA,0) -> 0 | J5: =IF(J4=Tenor,DSRA,0) -> 0 | K5: =IF(K4=Tenor,DSRA,0) -> 0 | ... AG5: =IF(AG4=Tenor,DSRA,0) -> 0
A7: Project cash flow, pre-tax | B7: $ | C7: =-Project_Capex+ITC_Proceeds -> -312934400 | D7: =CFADS!D7 -> 33469635 | E7: =CFADS!E7 -> 33072467 | F7: =CFADS!F7 -> 32671488 | G7: =CFADS!G7 -> 32266559 | H7: =CFADS!H7 -> 31857538 | I7: =CFADS!I7 -> 31444282 | J7: =CFADS!J7 -> 31026642 | K7: =CFADS!K7 -> 30604468 | ... AG7: =CFADS!AG7 -> 8588765.5
A8: Equity cash flow, pre-tax | B8: $ | C8: =-Equity -> -1.1400223e+08 | D8: =CFADS!D7-Debt_Sculpt!D14+D5 -> 8677312.7 | E8: =CFADS!E7-Debt_Sculpt!E14+E5 -> 8574343.3 | F8: =CFADS!F7-Debt_Sculpt!F14+F5 -> 8470385.8 | G8: =CFADS!G7-Debt_Sculpt!G14+G5 -> 8365404.1 | H8: =CFADS!H7-Debt_Sculpt!H14+H5 -> 8259361.8 | I8: =CFADS!I7-Debt_Sculpt!I14+I5 -> 8152221.3 | J8: =CFADS!J7-Debt_Sculpt!J14+J5 -> 8043944.3 | K8: =CFADS!K7-Debt_Sculpt!K14+K5 -> 7934491.7 | ... AG8: =CFADS!AG7-Debt_Sculpt!AG14+AG5 -> 8588765.5
A9: Project cash flow, after tax | B9: $ | C9: =C7 -> -312934400 | D9: =CFADS!D7-Tax_Rate*(CFADS!D7-Tax!D7) -> 41751859 | E9: =CFADS!E7-Tax_Rate*(CFADS!E7-Tax!E7) -> 50624606 | F9: =CFADS!F7-Tax_Rate*(CFADS!F7-Tax!F7) -> 40508890 | G9: =CFADS!G7-Tax_Rate*(CFADS!G7-Tax!G7) -> 34309630 | H9: =CFADS!H7-Tax_Rate*(CFADS!H7-Tax!H7) -> 33986504 | I9: =CFADS!I7-Tax_Rate*(CFADS!I7-Tax!I7) -> 29250507 | J9: =CFADS!J7-Tax_Rate*(CFADS!J7-Tax!J7) -> 24511048 | K9: =CFADS!K7-Tax_Rate*(CFADS!K7-Tax!K7) -> 24177530 | ... AG9: =CFADS!AG7-Tax_Rate*(CFADS!AG7-Tax!AG7) -> 6785124.7
A10: Equity cash flow, after tax | B10: $ | C10: =C8 -> -1.1400223e+08 | D10: =D8-Tax!D9 -> 20210195 | E10: =E8-Tax!E9 -> 29241021 | F10: =F8-Tax!F9 -> 19281034 | G10: =G8-Tax!G9 -> 13234936 | H10: =H8-Tax!H9 -> 13062170 | I10: =I8-Tax!I9 -> 8473478 | J10: =J8-Tax!J9 -> 3877990.6 | K10: =K8-Tax!K9 -> 3684814.5 | ... AG10: =AG8-Tax!AG9 -> 6785124.7
A12: Project IRR, pre-tax | B12: % | C12: =IFERROR(IRR(C7:AG7),"n/m") -> 0.074437961
A13: Equity IRR, pre-tax | B13: % | C13: =IFERROR(IRR(C8:AG8),"n/m") -> 0.062792016
A14: Project IRR, after tax | B14: % | C14: =IFERROR(IRR(C9:AG9),"n/m") -> 0.073088701
A15: Equity IRR, after tax | B15: % | C15: =IFERROR(IRR(C10:AG10),"n/m") -> 0.081350134
A16: Equity multiple, pre-tax | B16: x | C16: =SUM(D8:AG8)/Equity -> 2.3067794
A17: Check: NPV at the pre-tax equity IRR | B17: $ | C17: =IF(ISNUMBER(Equity_IRR),NPV(Equity_IRR,D8:AG8)+C8,0) -> 1.0430813e-07
A18: Check: NPV at the after-tax equity IRR | B18: $ | C18: =IF(ISNUMBER(Equity_IRR_AT),NPV(Equity_IRR_AT,D10:AG10)+C10,0) -> 2.9802322e-08
A20: Output and emissions
A21: Generation, year 1 (P50) | B21: MWh | C21: =Generation!D12 -> 535483.03
A22: Net capacity factor, year 1 | B22: % | C22: =Generation!D12/(PV_MWac*Hours_Per_Year) -> 0.305641
A23: Grid emissions displaced, year 1 (average rate) | B23: tCO2e | C23: =Generation!D12*Grid_CO2e_lb_MWh/lb_per_t -> 188070.74
A24: Grid emissions displaced, project life | B24: tCO2e | C24: =SUM(Generation!D12:AG12)*Grid_CO2e_lb_MWh/lb_per_t -> 5105156.2
A25: Project capex per tonne displaced | B25: $/tCO2e | C25: =Project_Capex/tCO2e_Avoided_Life -> 83.441913

Sheet Scenarios
A1: Stress cases
A2: Rating-agency style: the operating case runs at one-year P90 (Downside) and one-year P99 (Severe) output in every year against the debt schedule fixed at close, with a lower merchant tail. A rate shock and an EPC overrun act at close: the first re-sizes the sculpted debt, the second is funded with equity.
A4: Case currently shown (Inputs!Case_Select) | B4: =CHOOSE(Case_Select,"Base","Downside","Severe") -> Base
A5: Senior debt | B5: =Debt -> 2.2240406e+08
A6: Minimum DSCR (operating case) | B6: =Min_DSCR_Op -> 1.35
A7: Average DSCR (operating case) | B7: =Avg_DSCR_Op -> 1.35
A8: LLCR (operating case) | B8: =LLCR_Op -> 1.35
A9: Years in distribution lock-up | B9: =Lockup_Years -> 0
A10: Years below the default trigger | B10: =Default_Years -> 0
A11: Sponsor equity | B11: =Equity -> 1.1400223e+08
A12: Equity IRR, pre-tax | B12: =Equity_IRR -> 0.062792016
A13: Equity IRR, after tax | B13: =Equity_IRR_AT -> 0.081350134
A14: Project IRR, pre-tax | B14: =Project_IRR -> 0.074437961
A16: Snapshot of all three cases (Python engine at build time; set Case_Select to reproduce any column live)
A17: Metric | B17: Base | C17: Downside | D17: Severe
A18: Senior debt | B18: 2.2240406e+08 | C18: 2.0839515e+08 | D18: 1.9574486e+08
A19: Minimum DSCR (operating case) | B19: 1.35 | C19: 1.2000632 | D19: 1.0778418
A20: Average DSCR (operating case) | B20: 1.35 | C20: 1.2515823 | D20: 1.1713568
A21: LLCR (operating case) | B21: 1.35 | C21: 1.2594699 | D21: 1.1863208
A22: Years in distribution lock-up | B22: 0 | C22: 0 | D22: 3
A23: Years below the default trigger | B23: 0 | C23: 0 | D23: 0
A24: Sponsor equity | B24: 1.1400223e+08 | C24: 1.596489e+08 | D24: 2.0387813e+08
A25: Equity IRR, pre-tax | B25: 0.062792016 | C25: 0.0042898767 | D25: -0.049186463
A26: Equity IRR, after tax | B26: 0.081350134 | C26: 0.011066104 | D26: -0.050063871
A27: Project IRR, pre-tax | B27: 0.074437961 | C27: 0.048727129 | D27: 0.026028148
A29: One factor at a time from the base case: minimum operating DSCR
A30: Lever | B30: Value | C30: Change from base
A31: P99 output (1-yr) | B31: 1.0778418 | C31: -0.27215817
A32: P90 output (1-yr) | B32: 1.2000632 | C32: -0.14993677
A33: Battery toll -25% | B33: 1.35 | C33: -2.220446e-16
A34: Merchant tail -50% | B34: 1.35 | C34: 0
A35: EPC overrun +20% | B35: 1.35 | C35: 0
A36: Rate +200 bp at close | B36: 1.35 | C36: 0
A37: No solar tax credit | B37: 1.35 | C37: 0
A39: One factor at a time from the base case: after-tax equity IRR
A40: Lever | B40: Value | C40: Change from base
A41: No solar tax credit | B41: 0.023777258 | C41: -0.057572875
A42: EPC overrun +20% | B42: 0.035101038 | C42: -0.046249095
A43: P99 output (1-yr) | B43: 0.03536567 | C43: -0.045984463
A44: Battery toll -25% | B44: 0.051777626 | C44: -0.029572507
...

Sheet Checks
A1: Checks
A2: Each check returns TRUE when it passes.
A4: Sources = uses | C4: =ABS(Total_Sources-Total_Uses)<=Tolerance -> TRUE
A5: Debt = NPV of scheduled debt service at the coupon | C5: =ABS(NPV(Rate,Debt_Sculpt!D14:AG14)-Debt)<=Tolerance*Debt -> TRUE
A6: Debt fully repaid at maturity | C6: =ABS(INDEX(Debt_Sculpt!D18:AG18,1,Tenor))<=Tolerance*Debt -> TRUE
A7: Balance never negative | C7: =MIN(Debt_Sculpt!D18:AG18)>=-Tolerance*Debt -> TRUE
A8: Scheduled service = target service x scale in every year | C8: =MAX(Ratios!D11:AG11)<=Tolerance*Debt -> TRUE
A9: P50 DSCR at or above target | C9: =Min_DSCR_P50>=DSCR_P50_Target-Tolerance -> TRUE
A10: P90 DSCR at or above target | C10: =Min_DSCR_P90>=DSCR_P90_Target-Tolerance -> TRUE
A11: Debt within gearing cap | C11: =Debt<=Debt_Capacity_Gearing+Tolerance -> TRUE
A12: Debt matures inside the PPA and the model | C12: =AND(Tenor<=PPA_Term,Tenor<=COUNT(Generation!D4:AG4)) -> TRUE
A13: NPV at the equity IRRs is zero | C13: =AND(ABS(Equity_NPV_At_IRR)<=Tolerance*Equity,ABS(Equity_NPV_At_IRR_AT)<=Tolerance*Equity) -> TRUE
A15: All checks pass | C15: =AND(Check_SU,Check_Debt_PV,Check_Repaid,Check_No_Negative,Check_Parity,Check_DSCR_P50,Check_DSCR_P90,Check_Gearing,Check_Tenor,Check_IRR) -> TRUE
